Workbook
Name ввв: '[15]ОДТ и ГЦТ'!#REF!
Name Вес_коэфф_Доля_ОТА_ЮЛ: #REF!
Name Вес_коэфф_Доход_на_1_ОТА: #REF!
Name Вес_коэфф_Доход_на_1_ОТА_темп_роста: #REF!
Name Вес_коэфф_Доходы_темп_роста: #REF!
Name Вес_коэфф_Заявки: #REF!
Name Вес_коэфф_ОТА_темп_роста: #REF!
Name Вес_коэфф_Темп_прироста: #REF!
Name Вес_коэфф_Тлф_плотность: #REF!
Name Вес_коэфф_Трафик_темп_роста: #REF!
Name Вес_коэфф_Эксперт_оценка: #REF!
Name ГЦТ_Алматытелеком_Выдел.интернет: '[15]ОДТ и ГЦТ'!#REF!
Name ГЦТ_Алматытелеком_Выдел.интернет_2002: '[15]ОДТ и ГЦТ'!#REF!
Name ГЦТ_Алматытелеком_ADSL: '[15]ОДТ и ГЦТ'!#REF!
Name ГЦТ_Алматытелеком_ADSL_2002: '[15]ОДТ и ГЦТ'!#REF!
Name ГЦТ_Астанателеком_2002: '[15]ОДТ и ГЦТ'!#REF!
Name д: #REF!
Name ен: '[16]I. Прогноз доходов'!$F$31
Name Интернет_скоростя: [17]!Таблица1[#Data]
Name й: '[7]I. Прогноз доходов'!$F$31
Name ййй: #REF!
Name йййй: #REF!
Name ййййй: '[18]25. Hidden'!$C$40
Name йййййй: '[18]2. Inputs'!$D$22
Name Карагандинская_ОДТ_2002: '[15]ОДТ и ГЦТ'!#REF!
Name Макс_знач_Доля_ЮЛ: #REF!
Name Макс_знач_Доход_на_1_ОТА: #REF!
Name Макс_знач_Доход_на_1_ОТА_темп_роста: #REF!
Name Макс_знач_Доходы_темпы_роста: #REF!
Name Макс_знач_ОТА_темпы_роста: #REF!
Name Макс_знач_Ср_возраст_Мод: #REF!
Name Макс_знач_Ср_возраст_Разв: #REF!
Name Макс_знач_Тлф_плотность: #REF!
Name Макс_знач_Трафик_темпы_роста: #REF!
Name Менеджер: [19]!Таблица7[#Data]
Name Мин_знач_Доля_ЮЛ: #REF!
Name Мин_знач_Доход_на_1_ОТА: #REF!
Name Мин_знач_Доход_на_1_ОТА_темп_роста: #REF!
Name Мин_знач_Доходы_темпы_роста: #REF!
Name Мин_знач_ОТА_темпы_роста: #REF!
Name Мин_знач_Ср_возраст_Мод: #REF!
Name Мин_знач_Ср_возраст_Разв: #REF!
Name Мин_знач_Тлф_плотность: #REF!
Name мин_знач_Трафик_темпы_роста: #REF!
Name Мред_знач_Трафик_темпы_роста: #REF!
Name Нумерация: #REF!
Name Отар: #REF!
Name Отар_1: #REF!
Name Отар_2: #REF!
Name Подключение_Выдел.Интернет: '[15]ОДТ и ГЦТ'!#REF!
Name Подключение_ADSL: '[15]ОДТ и ГЦТ'!#REF!
Name Поставщики: #REF!
Name Рост_от_разблокировки: '[20]I. Прогноз доходов'!$F$32
Name Рост_от_цифровизации: '[20]I. Прогноз доходов'!$F$31
Name Рост_от_цифровизации_МСС: '[21]I. Прогноз доходов'!$F$32
Name С_Казахстанская_ОДТ_2002: '[15]ОДТ и ГЦТ'!#REF!
Name СВОД_ВПН1: #REF!
Name Скидка_на_подключение_ОТА: '[22]2.2.I. Прогноз доходов'!$F$30
Name Сред_знач_Доля_ЮЛ: #REF!
Name Сред_знач_Доход_на_1_ОТА: #REF!

Sheet ГУ Пункты пропуска
A1: №п/п | B1: Подразделение (центральное / областное) | C1: Наименование ГУ | D1: Физический адрес | E1: Из списка исходного СОИ | F1: Статус строительства ВОЛС | G1: Статус подключения | H1: Готовность ПСД | I1: КВЭП
A2: Завершены работы
A3: 1 | B3: ДГД по Актюбинской области | C3: ПУНКТ ПРОПУСКА «КАРАШАТАУ» | D3: Актюбинская область, Айтекебийский район, м/у п. Комсомол и п. Карашатау, 380 метров от ЛГГ | E3: Нет (новый) | F3: Завершен | G3: Наряд | H3: готов | I3: 46101
A4: 2 | B4: ДГД по Алматинской области | C4: ПУНКТ ПРОПУСКА «КЕГЕН» (АВТОМОБИЛЬНЫЙ) | D4: Алматинская область, Райымбекский район, 12 км от н.п.Каркара, 20 м от ЛГГ | E4: Да | F4: Завершен | G4: Наряд | H4: готов | I4: 46101
A5: 3 | B5: ДГД по Атырауской области | C5: ПУНКТ ПРОПУСКА «КУРМАНГАЗЫ» | D5: Атырауская область. Н.п.Караозек | E5: Нет (новый) | F5: Завершен | G5: Наряд | H5: готов | I5: 46101
A6: 4 | B6: ДГД по Жамбылской области | C6: ПУНКТ ПРОПУСКА «АЙША БИБИ» | D6: Жамбылская область, Жамбылский район село Гродеково | E6: Нет (новый) | F6: Завершен | G6: Подключен | H6: готов | I6: 46101
A7: 5 | B7: ДГД по ЗКО | C7: ПУНКТ ПРОПУСКА «ЖАНИБЕК» (АВТОМОБИЛЬНЫЙ) ЗКО | D7: п. Жанибек, Жанибекского сельского округа, Жанибекского района, 10 метров от ЛГГ | E7: Нет (новый) | F7: Завершен | G7: Наряд | H7: готов | I7: 46101
A8: 6 | B8: ДГД по ЗКО | C8: ПУНКТ ПРОПУСКА «АКСАЙ» (АВТОМОБИЛЬНЫЙ) ЗКО | D8: Бурлинский район от 9 км от н.п.Жарсуат, 150 м от ЛГГ | E8: Да | F8: Завершен | G8: Наряд | H8: готов | I8: 46101
A9: 7 | B9: ДГД по Карагандинской области | C9: Подразделение таможенного поста «Караганда-ЦТО» | D9: г. Караганда, ул. Сатпаева, 204, ТОО «СВХ Техносклад» | E9: Нет (новый) | F9: Завершен | G9: Подключен | H9: готов | I9: 46101
A10: 8 | B10: ДГД по Костанайской области | C10: ПУНКТ ПРОПУСКА «АКБАЛШИК» | D10: Костанайская область, 3 км от н.п. Белоглинка, Узынкольский р-н, 400 м от ЛГГ | E10: Нет (новый) | F10: Завершен | G10: Наряд | H10: готов | I10: 46101
A11: 9 | B11: ДГД по Костанайской области | C11: ПУНКТ ПРОПУСКА «АЯТ» | D11: Костанайская область, в 500 м. от н.п. Варваринка, Тарановского района, 4500 м от ЛГГ | E11: Нет (новый) | F11: Завершен | G11: Наряд | H11: готов | I11: 46101
A12: 10 | B12: ДГД по Мангистауской области | C12: Таможенный пост «Кара Шекпен» | D12: Мангистауская обл.,Тупкараганский район, п. Баутино, ул. Мунайши 2 | E12: Да | F12: Завершен | G12: Подключен | H12: готов | I12: 46101
A13: 11 | B13: ДГД по области Абай | C13: ПУНКТ ПРОПУСКА «ЖЕЗКЕНТ» (АВТОМОБИЛЬНЫЙ) | D13: Бородулихинский р-н, с. Жезкент, 1500м от ЛГГ | E13: Нет (новый) | F13: Завершен | G13: Наряд | H13: готов | I13: 46101
A14: 12 | B14: ДГД по Павлодарской области | C14: ПУНКТ ПРОПУСКА «УРЛИТОБЕ» | D14: Павлодарская область, на автомагистрали Павлодар-Омск, 220 км от г. Павлодар | E14: Нет (новый) | F14: Завершен | G14: Наряд | H14: готов | I14: 46101
... A18: 16 | B18: ДГД по СКО | C18: Таможенный пост «Петропавловск-Центр таможенного оформления» | D18: СКО, г. Петропавловск, ул. Мухтара Ауэзова, 297 | E18: Нет (новый) | F18: Завершен | G18: Подключен | H18: готов, без коммуникации | I18: 46101
A19: 17 | B19: ДГД по СКО | C19: ДГД по СКО | D19: СКО, г. Петропавловск, ул. Лесная 67 (ЖД пункт пропуска УЭК) | H19: готов | I19: 46101
A20: 18 | B20: ДГД по области Жетысу | C20: ТП Талдыкорган | D20: Область Жетысу,Талдыкорган ул. Жансугурова 111 | E20: Нет (новый) | F20: 46081 | G20: собственными силами
A22: В производстве
A23: 19 | B23: ДГД по Актюбинской области | C23: ПУНКТ ПРОПУСКА «АЛИМБЕТ» | D23: Актюбинская обл, Карагалинский район 12 км от пос. Алимбетовка | E23: Нет (новый) | F23: 46081 | G23: 46094 | H23: готов | I23: 46101
A24: 20 | B24: ДГД по Жамбылской области | C24: ПУНКТ ПРОПУСКА «Аухатты» | D24: Жамбылская область, Кордайский р-н, н.п. Аухатты, РУМПП "Оңтүстік", | E24: Нет (новый) | F24: 46081 | G24: 46085 | H24: готов, без коммуникации | I24: 46101
A25: 21 | B25: ДГД по Кызылординской области | C25: Таможенный пост «Байконыр» | D25: г. Байконыр, ул. Максимова, 8 | E25: Нет (новый) | F25: 46081 | G25: 46087 | H25: Ожидаем ТУ на прокладку по сущ тел канализации | I25: 46101
A26: 22 | B26: ДГД по Туркестанской области | C26: Таможенный пост «Туркестан Центр таможенного оформления» в г. Арыс | D26: г.Арыс ул.Шпал зауыты, участок 2084, на территории СВХ ТОО «Акжол Транс Трейд» | G26: 46094 | H26: готов | I26: 46101
E27: Нет (новый) | F27: 46096
A28: В производстве со сроком завершения СМР 15.04.2026 г.
A29: 23 | B29: ДГД по Костанайской области | C29: ПУНКТ ПРОПУСКА «КАЙРАК» | D29: Костанайская область, на 927 км автодороги М36 Астана-Екатеринбург, 500 м от ЛГГ | E29: Нет (новый) | F29: 46127 | G29: 46127 | H29: готов, без коммуникации | I29: 46171
A30: 24 | B30: ДГД по Костанайской области | C30: ПУНКТ ПРОПУСКА «КОНДЫБАЙ» | D30: Костанайская область, в 90 км. от г. Житикара, Житикаринского района, 350 м от ЛГГ | E30: Нет (новый) | F30: 46127 | G30: 46127 | H30: готов, без коммуникации | I30: 46171
A31: 25 | B31: ДГД по Костанайской области | C31: ПУНКТ ПРОПУСКА «ЖЕЛКУАР» | D31: Костанайская область, Житикаринский район, г. Житикара, 800 м от ЛГГ | E31: Нет (новый) | F31: 46127 | G31: 46127 | H31: готов, без коммуникации | I31: 46171
A32: 26 | B32: ДГД по Костанайской области | C32: ПУНКТ ПРОПУСКА «УБАГАН» | D32: Костанайская область, в 6 км. от п. Убаган, Узункольского района, 700 м от ЛГГ | E32: Нет (новый) | F32: 46127 | G32: 46127 | H32: готов, без коммуникации | I32: 46171
A33: 27 | B33: ДГД по области Абай | C33: ПУНКТ ПРОПУСКА «АУЫЛ» (АВТОМОБИЛЬНЫЙ) ВКО | D33: Бородулихинский р-н, станции Аул | E33: Да | F33: 46188 | G33: 46188 | H33: готов, без коммуникации | I33: 46171
A34: 28 | B34: ДГД по области Абай | C34: ПУНКТ ПРОПУСКА «КОЯНБАЙ» (АВТОМОБИЛЬНЫЙ) ВКО | D34: Бескарагайского р-не в 14 км от населенного пункта Коянбай, 200 м от ЛГГ | E34: Да | F34: 46188 | G34: 46188 | H34: готов, без коммуникации | I34: 46171
A35: 29 | B35: ДГД по области Абай | C35: ПУНКТ ПРОПУСКА «БАЙТАНАТ» (АВТОМОБИЛЬНЫЙ) ВКО | D35: Бородулихинский р-н, с. Байтанат, 12 км от ЛГГ | E35: Нет (новый) | F35: 46127 | G35: 46127 | H35: готов, без коммуникации | I35: 46171
A36: 30 | B36: ДГД по Павлодарской области | C36: ПУНКТ ПРОПУСКА «АМАНГЕЛЬДЫ» (АВТОМОБИЛЬНЫЙ) | D36: Павлодарская область, на автомагистрали Павлодар-Омск, 320 км от г. Павлодар | E36: Нет (новый) | F36: 46127 | G36: 46127 | H36: готов, без коммуникации | I36: 46171
A37: 31 | B37: ДГД по СКО | C37: ПУНКТ ПРОПУСКА «КЫЗЫЛЖАР» | D37: Кызылжарский район, 3 км от н.п. Красный Яр, 83 км от г. Петропавловск, 500 м от ЛГГ | E37: Нет (новый) | F37: 46127 | G37: 46127 | H37: готов, без коммуникации | I37: 46171
A38: 32 | B38: ДГД по СКО | C38: ПУНКТ ПРОПУСКА «БИДАИК» | D38: Ч.Уалихановский район 11 км от село Бидаик, 20 м от ЛГГ | E38: Нет (новый) | F38: 46127 | G38: 46127 | H38: готов, без коммуникации | I38: 46171
A39: 33 | B39: ДГД по СКО | C39: ПУНКТ ПРОПУСКА «ЖАНАЖОЛ» | D39: Мамлютский район село Чистое, 640 м от ЛГГ | E39: Нет (новый) | F39: 46127 | G39: 46127 | H39: готов, без коммуникации | I39: 46171
A40: 34 | B40: ДГД по СКО | C40: ПУНКТ ПРОПУСКА «ЖАНАЖОЛ» 2 | D40: Мамлютский район село Чистое, 640 м от ЛГГ Здание 2 | E40: Нет (новый) | F40: 46127 | G40: 46127 | H40: готов, без коммуникации | I40: 46171
A41: 35 | B41: ДГД по Атырауской области | C41: Таможенный пост "Тенгиз" | D41: Атырауская обл., Жылыойский район, гор. Кульсары, промзона Тенгизшевройл | E41: Нет (новый) | F41: 46096 | G41: 46096 | H41: готов, без коммуникации | I41: 46171
A42: 36 | B42: ДГД по Актюбинской области | C42: ПУНКТ ПРОПУСКА «ЖАЙСАН» | D42: Актюбинская область, Мартукский район, п. Жайсан, 5 метров от ЛГГ | G42: 46111 | H42: готов, без коммуникации | I42: 46171
A43: 37 | B43: ДГД по ВКО | C43: ПУНКТ ПРОПУСКА «УБА» (АВТОМОБИЛЬНЫЙ) | D43: н.п. Шемонаиха | G43: 46172 | H43: готов, без коммуникации | I43: 46171
A44: 38 | B44: ДГД по Актюбинской области | C44: Таможенный пост «Эмбi» | D44: Мугалжарский район, новая база УПТО и КО АО «СНПС-Актобемунайгаз» месторождение «Жанажол» | G44: 46111 | H44: готов, без коммуникации | I44: 46171

Sheet ПИР-ПСД
I1: Исходно-разрешительные документы | T1: Инженерные изыскания | Y1: Проектирование | AH1: Согласования | BC1: Землеустроительные работы | BH1: Экспертиза проекта | BJ1: Итоги
A2: Номер Заказа | B2: ПИР год реализации | C2: Подрядчик | D2: КАТО | E2: Область | F2: Район | G2: Сельский округ | H2: СНП | I2: Акт выбора трасс | K2: АПЗ | M2: Технические условия на подключение | O2: Постановление о разрешении на ПИР | Q2: Технические условия на пересечение | S2: Общий статус выполнения, % | T2: Инженерно геологические изыскания | V2: Инженерно-геодезические изыскания | X2: Общий статус выполнения, % | Y2: Рабочие чертежи | AA2: Сметная документация | AC2: Проект организации строительства | AE2: Экологическая часть проекта | AG2: Общий статус выполнения, % | AH2: Заключение историко-культурной экспертизы | AJ2: Письмо об отсутствии сибиреязвенных захоронений и скотомогильников | AL2: Протокол дозиметрического контроля | AN2: Протокол измерений содержания радона и продуктов его распада в воздухе | AP2: Согласование трассы ВОЛС с соответствующей Бассейновой водохозяйственной инспекцией | AR2: Согласование с АО "Авиационная администрация Казахстана" | AT2: Согласование трассы ВОЛС с местным Лесхозом | AV2: Согласование с владельцами пересекаемых коммуникаций | AX2: Согласование экологической части проекта | AZ2: Согласование проекта с Заказчиком | BB2: Общий статус выполнения, % | BC2: Землеотвод под ВОЛС (постановление, гос акт. серветут, распоряжение) | BE2: Изготовление землеустроительного проекта | BG2: Общий статус выполнения, % | BH2: Комплексная вневедомственная экспертиза проекта | BJ2: Проектная протяженность трассы ВОЛС после экспертизы, м | BK2: Плановая дата завершения проекта | BL2: Суммарная готовность (%)
I3: Информация | J3: да/нет | K3: Информация | L3: да/нет | M3: Информация | N3: да/нет | O3: Информация | P3: да/нет | Q3: Информация | R3: да/нет | T3: Информация | U3: да/нет | V3: Информация | W3: да/нет | Y3: Информация | Z3: % | AA3: Информация | AB3: % | AC3: Информация | AD3: да/нет | AE3: Информация | AF3: да/нет | AH3: Информация | AI3: да/нет | AJ3: Информация | AK3: да/нет | AL3: Информация | AM3: да/нет | AN3: Информация | AO3: да/нет | AP3: Информация | AQ3: да/нет | AR3: Информация | AS3: да/нет | AT3: Информация | AU3: да/нет | AV3: Информация | AW3: да/нет | AX3: Информация | AY3: да/нет | AZ3: Информация | BA3: да/нет | BC3: Информация | BD3: да/нет | BE3: Информация | BF3: да/нет | BH3: Информация | BI3: %
B4: 2026 | C4: ТОО "5А Engineering" | D4: 113241200 | E4: Акмолинская область | F4: Аккольский район | G4: Карасайский с.о. | H4: с.Карасай | I4: Имеется | J4: 1 | K4: на стадии подготовки | L4: 0.25 | M4: на стадии подготовки | N4: 0 | O4: на стадии подготовки | P4: 0 | Q4: на стадии подготовки | R4: 0 | S4: =(J4*'"Вес" ПИР'!$B$13+L4*'"Вес" ПИР'!$B$14+N4*'"Вес" ПИР'!$B$15+P4*'"Вес" ПИР'!$B$16+R4*'"Вес" ПИР'!$B$17)/100 -> 0.125 | T4: Готово | U4: 1 | V4: Готово | W4: 1 | X4: =(U4*'"Вес" ПИР'!$B$22+W4*'"Вес" ПИР'!$B$23)/100 -> 1 | Z4: 0.1 | AB4: 0 | AD4: 0 | AF4: 0 | AG4: =(Z4*'"Вес" ПИР'!$B$28+AB4*'"Вес" ПИР'!$B$29+AD4*'"Вес" ПИР'!$B$30+AF4*'"Вес" ПИР'!$B$31)/100 -> 0.075 | AJ4: на стадии подготовки | AP4: на стадии подготовки | AR4: на стадии подготовки | AT4: на стадии подготовки | BB4: =(AI4*'"Вес" ПИР'!$B$36+AK4*'"Вес" ПИР'!$B$37+AM4*'"Вес" ПИР'!$B$38+AO4*'"Вес" ПИР'!$B$39+AQ4*'"Вес" ПИР'!$B$40+AS4*'"Вес" ПИР'!$B$41+AU4*'"Вес" ПИР'!$B$42+AW4*'"Вес" ПИР'!$B$43+AY4*'"Вес" ПИР'!$B$44+BA4*'"Вес" ПИР'!$B$45)/100 -> 0 | BC4: на стадии подготовки | BE4: на стадии подготовки | BG4: =(BD4*'"Вес" ПИР'!$B$50+BF4*'"Вес" ПИР'!$B$51)/100 -> 0 | BI4: 0 | BK4: 46218 | BL4: =(S4*'"Вес" ПИР'!$B$3+X4*'"Вес" ПИР'!$B$4+AG4*'"Вес" ПИР'!$B$5+BB4*'"Вес" ПИР'!$B$6+BG4*'"Вес" ПИР'!$B$7+BI4*'"Вес" ПИР'!$B$8)/100 -> 0.1875
B5: 2026 | C5: ТОО "5А Engineering" | D5: 113241100 | E5: Акмолинская область | F5: Аккольский район | G5: Карасайский с.о. | H5: с.Кына | I5: Имеется | J5: 1 | K5: на стадии подготовки | M5: на стадии подготовки | O5: на стадии подготовки | Q5: на стадии подготовки | S5: =(J5*'"Вес" ПИР'!$B$13+L5*'"Вес" ПИР'!$B$14+N5*'"Вес" ПИР'!$B$15+P5*'"Вес" ПИР'!$B$16+R5*'"Вес" ПИР'!$B$17)/100 -> 0.05 | T5: Готово | V5: Готово | X5: =(U5*'"Вес" ПИР'!$B$22+W5*'"Вес" ПИР'!$B$23)/100 -> 0 | AG5: =(Z5*'"Вес" ПИР'!$B$28+AB5*'"Вес" ПИР'!$B$29+AD5*'"Вес" ПИР'!$B$30+AF5*'"Вес" ПИР'!$B$31)/100 -> 0 | AJ5: на стадии подготовки | AP5: на стадии подготовки | AR5: на стадии подготовки | AT5: на стадии подготовки | BB5: =(AI5*'"Вес" ПИР'!$B$36+AK5*'"Вес" ПИР'!$B$37+AM5*'"Вес" ПИР'!$B$38+AO5*'"Вес" ПИР'!$B$39+AQ5*'"Вес" ПИР'!$B$40+AS5*'"Вес" ПИР'!$B$41+AU5*'"Вес" ПИР'!$B$42+AW5*'"Вес" ПИР'!$B$43+AY5*'"Вес" ПИР'!$B$44+BA5*'"Вес" ПИР'!$B$45)/100 -> 0 | BC5: на стадии подготовки | BE5: на стадии подготовки | BG5: =(BD5*'"Вес" ПИР'!$B$50+BF5*'"Вес" ПИР'!$B$51)/100 -> 0 | BI5: 0 | BK5: 46218 | BL5: =(S5*'"Вес" ПИР'!$B$3+X5*'"Вес" ПИР'!$B$4+AG5*'"Вес" ПИР'!$B$5+BB5*'"Вес" ПИР'!$B$6+BG5*'"Вес" ПИР'!$B$7+BI5*'"Вес" ПИР'!$B$8)/100 -> 0.00375
B6: 2026 | C6: ТОО "5А Engineering" | D6: 113241300 | E6: Акмолинская область | F6: Аккольский район | G6: Карасайский с.о. | H6: с.Сазды булак | I6: Имеется | J6: 1 | K6: на стадии подготовки | M6: на стадии подготовки | O6: на стадии подготовки | Q6: на стадии подготовки | S6: =(J6*'"Вес" ПИР'!$B$13+L6*'"Вес" ПИР'!$B$14+N6*'"Вес" ПИР'!$B$15+P6*'"Вес" ПИР'!$B$16+R6*'"Вес" ПИР'!$B$17)/100 -> 0.05 | T6: Готово | V6: Готово | X6: =(U6*'"Вес" ПИР'!$B$22+W6*'"Вес" ПИР'!$B$23)/100 -> 0 | AG6: =(Z6*'"Вес" ПИР'!$B$28+AB6*'"Вес" ПИР'!$B$29+AD6*'"Вес" ПИР'!$B$30+AF6*'"Вес" ПИР'!$B$31)/100 -> 0 | AJ6: на стадии подготовки | AP6: на стадии подготовки | AR6: на стадии подготовки | AT6: на стадии подготовки | BB6: =(AI6*'"Вес" ПИР'!$B$36+AK6*'"Вес" ПИР'!$B$37+AM6*'"Вес" ПИР'!$B$38+AO6*'"Вес" ПИР'!$B$39+AQ6*'"Вес" ПИР'!$B$40+AS6*'"Вес" ПИР'!$B$41+AU6*'"Вес" ПИР'!$B$42+AW6*'"Вес" ПИР'!$B$43+AY6*'"Вес" ПИР'!$B$44+BA6*'"Вес" ПИР'!$B$45)/100 -> 0 | BC6: на стадии подготовки | BE6: на стадии подготовки | BG6: =(BD6*'"Вес" ПИР'!$B$50+BF6*'"Вес" ПИР'!$B$51)/100 -> 0 | BI6: 0 | BK6: 46218 | BL6: =(S6*'"Вес" ПИР'!$B$3+X6*'"Вес" ПИР'!$B$4+AG6*'"Вес" ПИР'!$B$5+BB6*'"Вес" ПИР'!$B$6+BG6*'"Вес" ПИР'!$B$7+BI6*'"Вес" ПИР'!$B$8)/100 -> 0.00375
B7: 2026 | C7: ТОО "5А Engineering" | D7: 113247300 | E7: Акмолинская область | F7: Аккольский район | G7: Наумовский с.о. | H7: с.Орнек | I7: Имеется | J7: 1 | K7: на стадии подготовки | M7: на стадии подготовки | O7: на стадии подготовки | Q7: на стадии подготовки | S7: =(J7*'"Вес" ПИР'!$B$13+L7*'"Вес" ПИР'!$B$14+N7*'"Вес" ПИР'!$B$15+P7*'"Вес" ПИР'!$B$16+R7*'"Вес" ПИР'!$B$17)/100 -> 0.05 | T7: Готово | V7: Готово | X7: =(U7*'"Вес" ПИР'!$B$22+W7*'"Вес" ПИР'!$B$23)/100 -> 0 | AG7: =(Z7*'"Вес" ПИР'!$B$28+AB7*'"Вес" ПИР'!$B$29+AD7*'"Вес" ПИР'!$B$30+AF7*'"Вес" ПИР'!$B$31)/100 -> 0 | AJ7: на стадии подготовки | AP7: на стадии подготовки | AR7: на стадии подготовки | AT7: на стадии подготовки | BB7: =(AI7*'"Вес" ПИР'!$B$36+AK7*'"Вес" ПИР'!$B$37+AM7*'"Вес" ПИР'!$B$38+AO7*'"Вес" ПИР'!$B$39+AQ7*'"Вес" ПИР'!$B$40+AS7*'"Вес" ПИР'!$B$41+AU7*'"Вес" ПИР'!$B$42+AW7*'"Вес" ПИР'!$B$43+AY7*'"Вес" ПИР'!$B$44+BA7*'"Вес" ПИР'!$B$45)/100 -> 0 | BC7: на стадии подготовки | BE7: на стадии подготовки | BG7: =(BD7*'"Вес" ПИР'!$B$50+BF7*'"Вес" ПИР'!$B$51)/100 -> 0 | BI7: 0 | BK7: 46218 | BL7: =(S7*'"Вес" ПИР'!$B$3+X7*'"Вес" ПИР'!$B$4+AG7*'"Вес" ПИР'!$B$5+BB7*'"Вес" ПИР'!$B$6+BG7*'"Вес" ПИР'!$B$7+BI7*'"Вес" ПИР'!$B$8)/100 -> 0.00375
B8: 2026 | C8: ТОО "5А Engineering" | D8: 113451100 | E8: Акмолинская область | F8: Аршалынский район | G8: Булаксайский с.о. | H8: с.Булаксай | I8: Имеется | J8: 1 | K8: на стадии подготовки | M8: на стадии подготовки | O8: на стадии подготовки | Q8: на стадии подготовки | S8: =(J8*'"Вес" ПИР'!$B$13+L8*'"Вес" ПИР'!$B$14+N8*'"Вес" ПИР'!$B$15+P8*'"Вес" ПИР'!$B$16+R8*'"Вес" ПИР'!$B$17)/100 -> 0.05 | T8: 01.12.2025-30.03.2026 | V8: 01.12.2025-30.03.2026 | X8: =(U8*'"Вес" ПИР'!$B$22+W8*'"Вес" ПИР'!$B$23)/100 -> 0 | AG8: =(Z8*'"Вес" ПИР'!$B$28+AB8*'"Вес" ПИР'!$B$29+AD8*'"Вес" ПИР'!$B$30+AF8*'"Вес" ПИР'!$B$31)/100 -> 0 | AJ8: на стадии подготовки | AP8: на стадии подготовки | AR8: на стадии подготовки | AT8: на стадии подготовки | BB8: =(AI8*'"Вес" ПИР'!$B$36+AK8*'"Вес" ПИР'!$B$37+AM8*'"Вес" ПИР'!$B$38+AO8*'"Вес" ПИР'!$B$39+AQ8*'"Вес" ПИР'!$B$40+AS8*'"Вес" ПИР'!$B$41+AU8*'"Вес" ПИР'!$B$42+AW8*'"Вес" ПИР'!$B$43+AY8*'"Вес" ПИР'!$B$44+BA8*'"Вес" ПИР'!$B$45)/100 -> 0 | BC8: на стадии подготовки | BE8: на стадии подготовки | BG8: =(BD8*'"Вес" ПИР'!$B$50+BF8*'"Вес" ПИР'!$B$51)/100 -> 0 | BI8: 0 | BK8: 46266 | BL8: =(S8*'"Вес" ПИР'!$B$3+X8*'"Вес" ПИР'!$B$4+AG8*'"Вес" ПИР'!$B$5+BB8*'"Вес" ПИР'!$B$6+BG8*'"Вес" ПИР'!$B$7+BI8*'"Вес" ПИР'!$B$8)/100 -> 0.00375
B9: 2026 | C9: ТОО "5А Engineering" | D9: 113453100 | E9: Акмолинская область | F9: Аршалынский район | G9: Сарабинский с.о. | H9: с.Сарыоба | I9: Имеется | J9: 1 | K9: на стадии подготовки | M9: на стадии подготовки | O9: на стадии подготовки | Q9: на стадии подготовки | S9: =(J9*'"Вес" ПИР'!$B$13+L9*'"Вес" ПИР'!$B$14+N9*'"Вес" ПИР'!$B$15+P9*'"Вес" ПИР'!$B$16+R9*'"Вес" ПИР'!$B$17)/100 -> 0.05 | T9: 01.12.2025-30.03.2026 | V9: 01.12.2025-30.03.2026 | X9: =(U9*'"Вес" ПИР'!$B$22+W9*'"Вес" ПИР'!$B$23)/100 -> 0 | AG9: =(Z9*'"Вес" ПИР'!$B$28+AB9*'"Вес" ПИР'!$B$29+AD9*'"Вес" ПИР'!$B$30+AF9*'"Вес" ПИР'!$B$31)/100 -> 0 | AJ9: на стадии подготовки | AP9: на стадии подготовки | AR9: на стадии подготовки | AT9: на стадии подготовки | BB9: =(AI9*'"Вес" ПИР'!$B$36+AK9*'"Вес" ПИР'!$B$37+AM9*'"Вес" ПИР'!$B$38+AO9*'"Вес" ПИР'!$B$39+AQ9*'"Вес" ПИР'!$B$40+AS9*'"Вес" ПИР'!$B$41+AU9*'"Вес" ПИР'!$B$42+AW9*'"Вес" ПИР'!$B$43+AY9*'"Вес" ПИР'!$B$44+BA9*'"Вес" ПИР'!$B$45)/100 -> 0 | BC9: на стадии подготовки | BE9: на стадии подготовки | BG9: =(BD9*'"Вес" ПИР'!$B$50+BF9*'"Вес" ПИР'!$B$51)/100 -> 0 | BI9: 0 | BK9: 46266 | BL9: =(S9*'"Вес" ПИР'!$B$3+X9*'"Вес" ПИР'!$B$4+AG9*'"Вес" ПИР'!$B$5+BB9*'"Вес" ПИР'!$B$6+BG9*'"Вес" ПИР'!$B$7+BI9*'"Вес" ПИР'!$B$8)/100 -> 0.00375
B10: 2026 | C10: ТОО "5А Engineering" | D10: 113453500 | E10: Акмолинская область | F10: Аршалынский район | G10: Сарабинский с.о. | H10: ст.Сарыоба | I10: Имеется | J10: 1 | K10: на стадии подготовки | M10: на стадии подготовки | O10: на стадии подготовки | Q10: на стадии подготовки | S10: =(J10*'"Вес" ПИР'!$B$13+L10*'"Вес" ПИР'!$B$14+N10*'"Вес" ПИР'!$B$15+P10*'"Вес" ПИР'!$B$16+R10*'"Вес" ПИР'!$B$17)/100 -> 0.05 | T10: 01.12.2025-30.03.2026 | V10: 01.12.2025-30.03.2026 | X10: =(U10*'"Вес" ПИР'!$B$22+W10*'"Вес" ПИР'!$B$23)/100 -> 0 | AG10: =(Z10*'"Вес" ПИР'!$B$28+AB10*'"Вес" ПИР'!$B$29+AD10*'"Вес" ПИР'!$B$30+AF10*'"Вес" ПИР'!$B$31)/100 -> 0 | AJ10: на стадии подготовки | AP10: на стадии подготовки | AR10: на стадии подготовки | AT10: на стадии подготовки | BB10: =(AI10*'"Вес" ПИР'!$B$36+AK10*'"Вес" ПИР'!$B$37+AM10*'"Вес" ПИР'!$B$38+AO10*'"Вес" ПИР'!$B$39+AQ10*'"Вес" ПИР'!$B$40+AS10*'"Вес" ПИР'!$B$41+AU10*'"Вес" ПИР'!$B$42+AW10*'"Вес" ПИР'!$B$43+AY10*'"Вес" ПИР'!$B$44+BA10*'"Вес" ПИР'!$B$45)/100 -> 0 | BC10: на стадии подготовки | BE10: на стадии подготовки | BG10: =(BD10*'"Вес" ПИР'!$B$50+BF10*'"Вес" ПИР'!$B$51)/100 -> 0 | BI10: 0 | BK10: 46266 | BL10: =(S10*'"Вес" ПИР'!$B$3+X10*'"Вес" ПИР'!$B$4+AG10*'"Вес" ПИР'!$B$5+BB10*'"Вес" ПИР'!$B$6+BG10*'"Вес" ПИР'!$B$7+BI10*'"Вес" ПИР'!$B$8)/100 -> 0.00375
B11: 2026 | C11: ТОО "5А Engineering" | D11: 113651100 | E11: Акмолинская область | F11: Астраханский район | G11: Острогорский с.о. | H11: с.Новый Колутон | I11: Имеется | J11: 1 | K11: на стадии подготовки | M11: на стадии подготовки | O11: на стадии подготовки | Q11: на стадии подготовки | S11: =(J11*'"Вес" ПИР'!$B$13+L11*'"Вес" ПИР'!$B$14+N11*'"Вес" ПИР'!$B$15+P11*'"Вес" ПИР'!$B$16+R11*'"Вес" ПИР'!$B$17)/100 -> 0.05 | T11: 01.12.2025-30.03.2026 | V11: 01.12.2025-30.03.2026 | X11: =(U11*'"Вес" ПИР'!$B$22+W11*'"Вес" ПИР'!$B$23)/100 -> 0 | AG11: =(Z11*'"Вес" ПИР'!$B$28+AB11*'"Вес" ПИР'!$B$29+AD11*'"Вес" ПИР'!$B$30+AF11*'"Вес" ПИР'!$B$31)/100 -> 0 | AJ11: на стадии подготовки | AP11: на стадии подготовки | AR11: на стадии подготовки | AT11: на стадии подготовки | BB11: =(AI11*'"Вес" ПИР'!$B$36+AK11*'"Вес" ПИР'!$B$37+AM11*'"Вес" ПИР'!$B$38+AO11*'"Вес" ПИР'!$B$39+AQ11*'"Вес" ПИР'!$B$40+AS11*'"Вес" ПИР'!$B$41+AU11*'"Вес" ПИР'!$B$42+AW11*'"Вес" ПИР'!$B$43+AY11*'"Вес" ПИР'!$B$44+BA11*'"Вес" ПИР'!$B$45)/100 -> 0 | BC11: на стадии подготовки | BE11: на стадии подготовки | BG11: =(BD11*'"Вес" ПИР'!$B$50+BF11*'"Вес" ПИР'!$B$51)/100 -> 0 | BI11: 0 | BK11: 46266 | BL11: =(S11*'"Вес" ПИР'!$B$3+X11*'"Вес" ПИР'!$B$4+AG11*'"Вес" ПИР'!$B$5+BB11*'"Вес" ПИР'!$B$6+BG11*'"Вес" ПИР'!$B$7+BI11*'"Вес" ПИР'!$B$8)/100 -> 0.00375
B12: 2026 | C12: ТОО "5А Engineering" | D12: 114655300 | E12: Акмолинская область | F12: Ерейментауский район | G12: Еркиншиликский с.о. | H12: с.Енбек | I12: Имеется | J12: 1 | K12: на стадии подготовки | M12: на стадии подготовки | O12: на стадии подготовки | Q12: на стадии подготовки | S12: =(J12*'"Вес" ПИР'!$B$13+L12*'"Вес" ПИР'!$B$14+N12*'"Вес" ПИР'!$B$15+P12*'"Вес" ПИР'!$B$16+R12*'"Вес" ПИР'!$B$17)/100 -> 0.05 | T12: Готово | V12: Готово | X12: =(U12*'"Вес" ПИР'!$B$22+W12*'"Вес" ПИР'!$B$23)/100 -> 0 | AG12: =(Z12*'"Вес" ПИР'!$B$28+AB12*'"Вес" ПИР'!$B$29+AD12*'"Вес" ПИР'!$B$30+AF12*'"Вес" ПИР'!$B$31)/100 -> 0 | AJ12: на стадии подготовки | AP12: на стадии подготовки | AR12: на стадии подготовки | AT12: на стадии подготовки | BB12: =(AI12*'"Вес" ПИР'!$B$36+AK12*'"Вес" ПИР'!$B$37+AM12*'"Вес" ПИР'!$B$38+AO12*'"Вес" ПИР'!$B$39+AQ12*'"Вес" ПИР'!$B$40+AS12*'"Вес" ПИР'!$B$41+AU12*'"Вес" ПИР'!$B$42+AW12*'"Вес" ПИР'!$B$43+AY12*'"Вес" ПИР'!$B$44+BA12*'"Вес" ПИР'!$B$45)/100 -> 0 | BC12: на стадии подготовки | BE12: на стадии подготовки | BG12: =(BD12*'"Вес" ПИР'!$B$50+BF12*'"Вес" ПИР'!$B$51)/100 -> 0 | BI12: 0 | BK12: 46218 | BL12: =(S12*'"Вес" ПИР'!$B$3+X12*'"Вес" ПИР'!$B$4+AG12*'"Вес" ПИР'!$B$5+BB12*'"Вес" ПИР'!$B$6+BG12*'"Вес" ПИР'!$B$7+BI12*'"Вес" ПИР'!$B$8)/100 -> 0.00375
B13: 2026 | C13: ТОО "5А Engineering" | D13: 114639100 | E13: Акмолинская область | F13: Ерейментауский район | G13: с.Бозтал | H13: с.Бозтал | I13: Имеется | J13: 1 | K13: на стадии подготовки | M13: на стадии подготовки | O13: на стадии подготовки | Q13: на стадии подготовки | S13: =(J13*'"Вес" ПИР'!$B$13+L13*'"Вес" ПИР'!$B$14+N13*'"Вес" ПИР'!$B$15+P13*'"Вес" ПИР'!$B$16+R13*'"Вес" ПИР'!$B$17)/100 -> 0.05 | T13: Готово | V13: Готово | X13: =(U13*'"Вес" ПИР'!$B$22+W13*'"Вес" ПИР'!$B$23)/100 -> 0 | AG13: =(Z13*'"Вес" ПИР'!$B$28+AB13*'"Вес" ПИР'!$B$29+AD13*'"Вес" ПИР'!$B$30+AF13*'"Вес" ПИР'!$B$31)/100 -> 0 | AJ13: на стадии подготовки | AP13: на стадии подготовки | AR13: на стадии подготовки | AT13: на стадии подготовки | BB13: =(AI13*'"Вес" ПИР'!$B$36+AK13*'"Вес" ПИР'!$B$37+AM13*'"Вес" ПИР'!$B$38+AO13*'"Вес" ПИР'!$B$39+AQ13*'"Вес" ПИР'!$B$40+AS13*'"Вес" ПИР'!$B$41+AU13*'"Вес" ПИР'!$B$42+AW13*'"Вес" ПИР'!$B$43+AY13*'"Вес" ПИР'!$B$44+BA13*'"Вес" ПИР'!$B$45)/100 -> 0 | BC13: на стадии подготовки | BE13: на стадии подготовки | BG13: =(BD13*'"Вес" ПИР'!$B$50+BF13*'"Вес" ПИР'!$B$51)/100 -> 0 | BI13: 0 | BK13: 46218 | BL13: =(S13*'"Вес" ПИР'!$B$3+X13*'"Вес" ПИР'!$B$4+AG13*'"Вес" ПИР'!$B$5+BB13*'"Вес" ПИР'!$B$6+BG13*'"Вес" ПИР'!$B$7+BI13*'"Вес" ПИР'!$B$8)/100 -> 0.00375
B14: 2026 | C14: ТОО "5А Engineering" | D14: 114837300 | E14: Акмолинская область | F14: Есильский район | G14: Бузулукский с.о. | H14: с.Сурган | I14: Имеется | J14: 1 | K14: на стадии подготовки | M14: на стадии подготовки | O14: на стадии подготовки | Q14: на стадии подготовки | S14: =(J14*'"Вес" ПИР'!$B$13+L14*'"Вес" ПИР'!$B$14+N14*'"Вес" ПИР'!$B$15+P14*'"Вес" ПИР'!$B$16+R14*'"Вес" ПИР'!$B$17)/100 -> 0.05 | T14: Готово | V14: Готово | X14: =(U14*'"Вес" ПИР'!$B$22+W14*'"Вес" ПИР'!$B$23)/100 -> 0 | AG14: =(Z14*'"Вес" ПИР'!$B$28+AB14*'"Вес" ПИР'!$B$29+AD14*'"Вес" ПИР'!$B$30+AF14*'"Вес" ПИР'!$B$31)/100 -> 0 | AJ14: на стадии подготовки | AP14: на стадии подготовки | AR14: на стадии подготовки | AT14: на стадии подготовки | BB14: =(AI14*'"Вес" ПИР'!$B$36+AK14*'"Вес" ПИР'!$B$37+AM14*'"Вес" ПИР'!$B$38+AO14*'"Вес" ПИР'!$B$39+AQ14*'"Вес" ПИР'!$B$40+AS14*'"Вес" ПИР'!$B$41+AU14*'"Вес" ПИР'!$B$42+AW14*'"Вес" ПИР'!$B$43+AY14*'"Вес" ПИР'!$B$44+BA14*'"Вес" ПИР'!$B$45)/100 -> 0 | BC14: на стадии подготовки | BE14: на стадии подготовки | BG14: =(BD14*'"Вес" ПИР'!$B$50+BF14*'"Вес" ПИР'!$B$51)/100 -> 0 | BI14: 0 | BK14: 31.09.2026 | BL14: =(S14*'"Вес" ПИР'!$B$3+X14*'"Вес" ПИР'!$B$4+AG14*'"Вес" ПИР'!$B$5+BB14*'"Вес" ПИР'!$B$6+BG14*'"Вес" ПИР'!$B$7+BI14*'"Вес" ПИР'!$B$8)/100 -> 0.00375
B15: 2026 | C15: ТОО "5А Engineering" | D15: 114845200 | E15: Акмолинская область | F15: Есильский район | G15: Жаныспайский с.о. | H15: с.Ковыльное | I15: Имеется | J15: 1 | K15: на стадии подготовки | M15: на стадии подготовки | O15: на стадии подготовки | Q15: на стадии подготовки | S15: =(J15*'"Вес" ПИР'!$B$13+L15*'"Вес" ПИР'!$B$14+N15*'"Вес" ПИР'!$B$15+P15*'"Вес" ПИР'!$B$16+R15*'"Вес" ПИР'!$B$17)/100 -> 0.05 | T15: Готово | V15: Готово | X15: =(U15*'"Вес" ПИР'!$B$22+W15*'"Вес" ПИР'!$B$23)/100 -> 0 | AG15: =(Z15*'"Вес" ПИР'!$B$28+AB15*'"Вес" ПИР'!$B$29+AD15*'"Вес" ПИР'!$B$30+AF15*'"Вес" ПИР'!$B$31)/100 -> 0 | AJ15: на стадии подготовки | AP15: на стадии подготовки | AR15: на стадии подготовки | AT15: на стадии подготовки | BB15: =(AI15*'"Вес" ПИР'!$B$36+AK15*'"Вес" ПИР'!$B$37+AM15*'"Вес" ПИР'!$B$38+AO15*'"Вес" ПИР'!$B$39+AQ15*'"Вес" ПИР'!$B$40+AS15*'"Вес" ПИР'!$B$41+AU15*'"Вес" ПИР'!$B$42+AW15*'"Вес" ПИР'!$B$43+AY15*'"Вес" ПИР'!$B$44+BA15*'"Вес" ПИР'!$B$45)/100 -> 0 | BC15: на стадии подготовки | BE15: на стадии подготовки | BG15: =(BD15*'"Вес" ПИР'!$B$50+BF15*'"Вес" ПИР'!$B$51)/100 -> 0 | BI15: 0 | BK15: 31.09.2026 | BL15: =(S15*'"Вес" ПИР'!$B$3+X15*'"Вес" ПИР'!$B$4+AG15*'"Вес" ПИР'!$B$5+BB15*'"Вес" ПИР'!$B$6+BG15*'"Вес" ПИР'!$B$7+BI15*'"Вес" ПИР'!$B$8)/100 -> 0.00375
B16: 2026 | C16: ТОО "5А Engineering" | D16: 114859200 | E16: Акмолинская область | F16: Есильский район | G16: Канай Бийский с.о. | H16: с.Иглик | I16: Имеется | J16: 1 | K16: на стадии подготовки | M16: на стадии подготовки | O16: на стадии подготовки | Q16: на стадии подготовки | S16: =(J16*'"Вес" ПИР'!$B$13+L16*'"Вес" ПИР'!$B$14+N16*'"Вес" ПИР'!$B$15+P16*'"Вес" ПИР'!$B$16+R16*'"Вес" ПИР'!$B$17)/100 -> 0.05 | T16: Готово | V16: Готово | X16: =(U16*'"Вес" ПИР'!$B$22+W16*'"Вес" ПИР'!$B$23)/100 -> 0 | AG16: =(Z16*'"Вес" ПИР'!$B$28+AB16*'"Вес" ПИР'!$B$29+AD16*'"Вес" ПИР'!$B$30+AF16*'"Вес" ПИР'!$B$31)/100 -> 0 | AJ16: на стадии подготовки | AP16: на стадии подготовки | AR16: на стадии подготовки | AT16: на стадии подготовки | BB16: =(AI16*'"Вес" ПИР'!$B$36+AK16*'"Вес" ПИР'!$B$37+AM16*'"Вес" ПИР'!$B$38+AO16*'"Вес" ПИР'!$B$39+AQ16*'"Вес" ПИР'!$B$40+AS16*'"Вес" ПИР'!$B$41+AU16*'"Вес" ПИР'!$B$42+AW16*'"Вес" ПИР'!$B$43+AY16*'"Вес" ПИР'!$B$44+BA16*'"Вес" ПИР'!$B$45)/100 -> 0 | BC16: на стадии подготовки | BE16: на стадии подготовки | BG16: =(BD16*'"Вес" ПИР'!$B$50+BF16*'"Вес" ПИР'!$B$51)/100 -> 0 | BI16: 0 | BK16: 31.09.2026 | BL16: =(S16*'"Вес" ПИР'!$B$3+X16*'"Вес" ПИР'!$B$4+AG16*'"Вес" ПИР'!$B$5+BB16*'"Вес" ПИР'!$B$6+BG16*'"Вес" ПИР'!$B$7+BI16*'"Вес" ПИР'!$B$8)/100 -> 0.00375
B17: 2026 | C17: ТОО "5А Engineering" | D17: 114857300 | E17: Акмолинская область | F17: Есильский район | G17: Красивинский с.о. | H17: с.Кумай | I17: Имеется | J17: 1 | K17: на стадии подготовки | M17: на стадии подготовки | O17: на стадии подготовки | Q17: на стадии подготовки | S17: =(J17*'"Вес" ПИР'!$B$13+L17*'"Вес" ПИР'!$B$14+N17*'"Вес" ПИР'!$B$15+P17*'"Вес" ПИР'!$B$16+R17*'"Вес" ПИР'!$B$17)/100 -> 0.05 | T17: Готово | V17: Готово | X17: =(U17*'"Вес" ПИР'!$B$22+W17*'"Вес" ПИР'!$B$23)/100 -> 0 | AG17: =(Z17*'"Вес" ПИР'!$B$28+AB17*'"Вес" ПИР'!$B$29+AD17*'"Вес" ПИР'!$B$30+AF17*'"Вес" ПИР'!$B$31)/100 -> 0 | AJ17: на стадии подготовки | AP17: на стадии подготовки | AR17: на стадии подготовки | AT17: на стадии подготовки | BB17: =(AI17*'"Вес" ПИР'!$B$36+AK17*'"Вес" ПИР'!$B$37+AM17*'"Вес" ПИР'!$B$38+AO17*'"Вес" ПИР'!$B$39+AQ17*'"Вес" ПИР'!$B$40+AS17*'"Вес" ПИР'!$B$41+AU17*'"Вес" ПИР'!$B$42+AW17*'"Вес" ПИР'!$B$43+AY17*'"Вес" ПИР'!$B$44+BA17*'"Вес" ПИР'!$B$45)/100 -> 0 | BC17: на стадии подготовки | BE17: на стадии подготовки | BG17: =(BD17*'"Вес" ПИР'!$B$50+BF17*'"Вес" ПИР'!$B$51)/100 -> 0 | BI17: 0 | BK17: 31.09.2026 | BL17: =(S17*'"Вес" ПИР'!$B$3+X17*'"Вес" ПИР'!$B$4+AG17*'"Вес" ПИР'!$B$5+BB17*'"Вес" ПИР'!$B$6+BG17*'"Вес" ПИР'!$B$7+BI17*'"Вес" ПИР'!$B$8)/100 -> 0.00375
B18: 2026 | C18: ТОО "5А Engineering" | D18: 115669100 | E18: Акмолинская область | F18: Зерендинский район | G18: Байтерекский с.о. | H18: с.Байтерек | I18: Имеется | J18: 1 | K18: на стадии подготовки | M18: на стадии подготовки | O18: на стадии подготовки | Q18: на стадии подготовки | S18: =(J18*'"Вес" ПИР'!$B$13+L18*'"Вес" ПИР'!$B$14+N18*'"Вес" ПИР'!$B$15+P18*'"Вес" ПИР'!$B$16+R18*'"Вес" ПИР'!$B$17)/100 -> 0.05 | T18: 01.12.2025-30.03.2026 | V18: 01.12.2025-30.03.2026 | X18: =(U18*'"Вес" ПИР'!$B$22+W18*'"Вес" ПИР'!$B$23)/100 -> 0 | AG18: =(Z18*'"Вес" ПИР'!$B$28+AB18*'"Вес" ПИР'!$B$29+AD18*'"Вес" ПИР'!$B$30+AF18*'"Вес" ПИР'!$B$31)/100 -> 0 | AJ18: на стадии подготовки | AP18: на стадии подготовки | AR18: на стадии подготовки | AT18: на стадии подготовки | BB18: =(AI18*'"Вес" ПИР'!$B$36+AK18*'"Вес" ПИР'!$B$37+AM18*'"Вес" ПИР'!$B$38+AO18*'"Вес" ПИР'!$B$39+AQ18*'"Вес" ПИР'!$B$40+AS18*'"Вес" ПИР'!$B$41+AU18*'"Вес" ПИР'!$B$42+AW18*'"Вес" ПИР'!$B$43+AY18*'"Вес" ПИР'!$B$44+BA18*'"Вес" ПИР'!$B$45)/100 -> 0 | BC18: на стадии подготовки | BE18: на стадии подготовки | BG18: =(BD18*'"Вес" ПИР'!$B$50+BF18*'"Вес" ПИР'!$B$51)/100 -> 0 | BI18: 0 | BK18: 46266 | BL18: =(S18*'"Вес" ПИР'!$B$3+X18*'"Вес" ПИР'!$B$4+AG18*'"Вес" ПИР'!$B$5+BB18*'"Вес" ПИР'!$B$6+BG18*'"Вес" ПИР'!$B$7+BI18*'"Вес" ПИР'!$B$8)/100 -> 0.00375
B19: 2026 | C19: ТОО "5А Engineering" | D19: 115669300 | E19: Акмолинская область | F19: Зерендинский район | G19: Байтерекский с.о. | H19: с.Ермаковка | I19: Имеется | J19: 1 | K19: на стадии подготовки | M19: на стадии подготовки | O19: на стадии подготовки | Q19: на стадии подготовки | S19: =(J19*'"Вес" ПИР'!$B$13+L19*'"Вес" ПИР'!$B$14+N19*'"Вес" ПИР'!$B$15+P19*'"Вес" ПИР'!$B$16+R19*'"Вес" ПИР'!$B$17)/100 -> 0.05 | T19: 01.12.2025-30.03.2026 | V19: 01.12.2025-30.03.2026 | X19: =(U19*'"Вес" ПИР'!$B$22+W19*'"Вес" ПИР'!$B$23)/100 -> 0 | AG19: =(Z19*'"Вес" ПИР'!$B$28+AB19*'"Вес" ПИР'!$B$29+AD19*'"Вес" ПИР'!$B$30+AF19*'"Вес" ПИР'!$B$31)/100 -> 0 | AJ19: на стадии подготовки | AP19: на стадии подготовки | AR19: на стадии подготовки | AT19: на стадии подготовки | BB19: =(AI19*'"Вес" ПИР'!$B$36+AK19*'"Вес" ПИР'!$B$37+AM19*'"Вес" ПИР'!$B$38+AO19*'"Вес" ПИР'!$B$39+AQ19*'"Вес" ПИР'!$B$40+AS19*'"Вес" ПИР'!$B$41+AU19*'"Вес" ПИР'!$B$42+AW19*'"Вес" ПИР'!$B$43+AY19*'"Вес" ПИР'!$B$44+BA19*'"Вес" ПИР'!$B$45)/100 -> 0 | BC19: на стадии подготовки | BE19: на стадии подготовки | BG19: =(BD19*'"Вес" ПИР'!$B$50+BF19*'"Вес" ПИР'!$B$51)/100 -> 0 | BI19: 0 | BK19: 46266 | BL19: =(S19*'"Вес" ПИР'!$B$3+X19*'"Вес" ПИР'!$B$4+AG19*'"Вес" ПИР'!$B$5+BB19*'"Вес" ПИР'!$B$6+BG19*'"Вес" ПИР'!$B$7+BI19*'"Вес" ПИР'!$B$8)/100 -> 0.00375
B20: 2026 | C20: ТОО "5А Engineering" | D20: 115669400 | E20: Акмолинская область | F20: Зерендинский район | G20: Байтерекский с.о. | H20: с.Красный Кордон | I20: Имеется | J20: 1 | K20: на стадии подготовки | M20: на стадии подготовки | O20: на стадии подготовки | Q20: на стадии подготовки | S20: =(J20*'"Вес" ПИР'!$B$13+L20*'"Вес" ПИР'!$B$14+N20*'"Вес" ПИР'!$B$15+P20*'"Вес" ПИР'!$B$16+R20*'"Вес" ПИР'!$B$17)/100 -> 0.05 | T20: 01.12.2025-30.03.2026 | V20: 01.12.2025-30.03.2026 | X20: =(U20*'"Вес" ПИР'!$B$22+W20*'"Вес" ПИР'!$B$23)/100 -> 0 | AG20: =(Z20*'"Вес" ПИР'!$B$28+AB20*'"Вес" ПИР'!$B$29+AD20*'"Вес" ПИР'!$B$30+AF20*'"Вес" ПИР'!$B$31)/100 -> 0 | AJ20: на стадии подготовки | AP20: на стадии подготовки | AR20: на стадии подготовки | AT20: на стадии подготовки | BB20: =(AI20*'"Вес" ПИР'!$B$36+AK20*'"Вес" ПИР'!$B$37+AM20*'"Вес" ПИР'!$B$38+AO20*'"Вес" ПИР'!$B$39+AQ20*'"Вес" ПИР'!$B$40+AS20*'"Вес" ПИР'!$B$41+AU20*'"Вес" ПИР'!$B$42+AW20*'"Вес" ПИР'!$B$43+AY20*'"Вес" ПИР'!$B$44+BA20*'"Вес" ПИР'!$B$45)/100 -> 0 | BC20: на стадии подготовки | BE20: на стадии подготовки | BG20: =(BD20*'"Вес" ПИР'!$B$50+BF20*'"Вес" ПИР'!$B$51)/100 -> 0 | BI20: 0 | BK20: 46266 | BL20: =(S20*'"Вес" ПИР'!$B$3+X20*'"Вес" ПИР'!$B$4+AG20*'"Вес" ПИР'!$B$5+BB20*'"Вес" ПИР'!$B$6+BG20*'"Вес" ПИР'!$B$7+BI20*'"Вес" ПИР'!$B$8)/100 -> 0.00375
B21: 2026 | C21: ТОО "5А Engineering" | D21: 115637400 | E21: Акмолинская область | F21: Зерендинский район | G21: Булакский с.о. | H21: с.Жанааул | I21: Имеется | J21: 1 | K21: на стадии подготовки | M21: на стадии подготовки | O21: на стадии подготовки | Q21: на стадии подготовки | S21: =(J21*'"Вес" ПИР'!$B$13+L21*'"Вес" ПИР'!$B$14+N21*'"Вес" ПИР'!$B$15+P21*'"Вес" ПИР'!$B$16+R21*'"Вес" ПИР'!$B$17)/100 -> 0.05 | T21: 01.12.2025-30.03.2026 | V21: 01.12.2025-30.03.2026 | X21: =(U21*'"Вес" ПИР'!$B$22+W21*'"Вес" ПИР'!$B$23)/100 -> 0 | AG21: =(Z21*'"Вес" ПИР'!$B$28+AB21*'"Вес" ПИР'!$B$29+AD21*'"Вес" ПИР'!$B$30+AF21*'"Вес" ПИР'!$B$31)/100 -> 0 | AJ21: на стадии подготовки | AP21: на стадии подготовки | AR21: на стадии подготовки | AT21: на стадии подготовки | BB21: =(AI21*'"Вес" ПИР'!$B$36+AK21*'"Вес" ПИР'!$B$37+AM21*'"Вес" ПИР'!$B$38+AO21*'"Вес" ПИР'!$B$39+AQ21*'"Вес" ПИР'!$B$40+AS21*'"Вес" ПИР'!$B$41+AU21*'"Вес" ПИР'!$B$42+AW21*'"Вес" ПИР'!$B$43+AY21*'"Вес" ПИР'!$B$44+BA21*'"Вес" ПИР'!$B$45)/100 -> 0 | BC21: на стадии подготовки | BE21: на стадии подготовки | BG21: =(BD21*'"Вес" ПИР'!$B$50+BF21*'"Вес" ПИР'!$B$51)/100 -> 0 | BI21: 0 | BK21: 46266 | BL21: =(S21*'"Вес" ПИР'!$B$3+X21*'"Вес" ПИР'!$B$4+AG21*'"Вес" ПИР'!$B$5+BB21*'"Вес" ПИР'!$B$6+BG21*'"Вес" ПИР'!$B$7+BI21*'"Вес" ПИР'!$B$8)/100 -> 0.00375
B22: 2026 | C22: ТОО "5А Engineering" | D22: 115637700 | E22: Акмолинская область | F22: Зерендинский район | G22: Булакский с.о. | H22: с.Карлыколь | I22: Имеется | J22: 1 | K22: на стадии подготовки | M22: на стадии подготовки | O22: на стадии подготовки | Q22: на стадии подготовки | S22: =(J22*'"Вес" ПИР'!$B$13+L22*'"Вес" ПИР'!$B$14+N22*'"Вес" ПИР'!$B$15+P22*'"Вес" ПИР'!$B$16+R22*'"Вес" ПИР'!$B$17)/100 -> 0.05 | T22: 01.12.2025-30.03.2026 | V22: 01.12.2025-30.03.2026 | X22: =(U22*'"Вес" ПИР'!$B$22+W22*'"Вес" ПИР'!$B$23)/100 -> 0 | AG22: =(Z22*'"Вес" ПИР'!$B$28+AB22*'"Вес" ПИР'!$B$29+AD22*'"Вес" ПИР'!$B$30+AF22*'"Вес" ПИР'!$B$31)/100 -> 0 | AJ22: на стадии подготовки | AP22: на стадии подготовки | AR22: на стадии подготовки | AT22: на стадии подготовки | BB22: =(AI22*'"Вес" ПИР'!$B$36+AK22*'"Вес" ПИР'!$B$37+AM22*'"Вес" ПИР'!$B$38+AO22*'"Вес" ПИР'!$B$39+AQ22*'"Вес" ПИР'!$B$40+AS22*'"Вес" ПИР'!$B$41+AU22*'"Вес" ПИР'!$B$42+AW22*'"Вес" ПИР'!$B$43+AY22*'"Вес" ПИР'!$B$44+BA22*'"Вес" ПИР'!$B$45)/100 -> 0 | BC22: на стадии подготовки | BE22: на стадии подготовки | BG22: =(BD22*'"Вес" ПИР'!$B$50+BF22*'"Вес" ПИР'!$B$51)/100 -> 0 | BI22: 0 | BK22: 46266 | BL22: =(S22*'"Вес" ПИР'!$B$3+X22*'"Вес" ПИР'!$B$4+AG22*'"Вес" ПИР'!$B$5+BB22*'"Вес" ПИР'!$B$6+BG22*'"Вес" ПИР'!$B$7+BI22*'"Вес" ПИР'!$B$8)/100 -> 0.00375
B23: 2026 | C23: ТОО "5А Engineering" | D23: 115643600 | E23: Акмолинская область | F23: Зерендинский район | G23: Викторовский с.о. | H23: с.Богенбай би | I23: Имеется | J23: 1 | K23: на стадии подготовки | M23: на стадии подготовки | O23: на стадии подготовки | Q23: на стадии подготовки | S23: =(J23*'"Вес" ПИР'!$B$13+L23*'"Вес" ПИР'!$B$14+N23*'"Вес" ПИР'!$B$15+P23*'"Вес" ПИР'!$B$16+R23*'"Вес" ПИР'!$B$17)/100 -> 0.05 | T23: 01.12.2025-30.03.2026 | V23: 01.12.2025-30.03.2026 | X23: =(U23*'"Вес" ПИР'!$B$22+W23*'"Вес" ПИР'!$B$23)/100 -> 0 | AG23: =(Z23*'"Вес" ПИР'!$B$28+AB23*'"Вес" ПИР'!$B$29+AD23*'"Вес" ПИР'!$B$30+AF23*'"Вес" ПИР'!$B$31)/100 -> 0 | AJ23: на стадии подготовки | AP23: на стадии подготовки | AR23: на стадии подготовки | AT23: на стадии подготовки | BB23: =(AI23*'"Вес" ПИР'!$B$36+AK23*'"Вес" ПИР'!$B$37+AM23*'"Вес" ПИР'!$B$38+AO23*'"Вес" ПИР'!$B$39+AQ23*'"Вес" ПИР'!$B$40+AS23*'"Вес" ПИР'!$B$41+AU23*'"Вес" ПИР'!$B$42+AW23*'"Вес" ПИР'!$B$43+AY23*'"Вес" ПИР'!$B$44+BA23*'"Вес" ПИР'!$B$45)/100 -> 0 | BC23: на стадии подготовки | BE23: на стадии подготовки | BG23: =(BD23*'"Вес" ПИР'!$B$50+BF23*'"Вес" ПИР'!$B$51)/100 -> 0 | BI23: 0 | BK23: 46266 | BL23: =(S23*'"Вес" ПИР'!$B$3+X23*'"Вес" ПИР'!$B$4+AG23*'"Вес" ПИР'!$B$5+BB23*'"Вес" ПИР'!$B$6+BG23*'"Вес" ПИР'!$B$7+BI23*'"Вес" ПИР'!$B$8)/100 -> 0.00375
B24: 2026 | C24: ТОО "5А Engineering" | D24: 115630380 | E24: Акмолинская область | F24: Зерендинский район | G24: Зерендинский с.о. | H24: с.Коктерек | I24: Имеется | J24: 1 | K24: на стадии подготовки | M24: на стадии подготовки | O24: на стадии подготовки | Q24: на стадии подготовки | S24: =(J24*'"Вес" ПИР'!$B$13+L24*'"Вес" ПИР'!$B$14+N24*'"Вес" ПИР'!$B$15+P24*'"Вес" ПИР'!$B$16+R24*'"Вес" ПИР'!$B$17)/100 -> 0.05 | T24: 01.12.2025-30.03.2026 | V24: 01.12.2025-30.03.2026 | X24: =(U24*'"Вес" ПИР'!$B$22+W24*'"Вес" ПИР'!$B$23)/100 -> 0 | AG24: =(Z24*'"Вес" ПИР'!$B$28+AB24*'"Вес" ПИР'!$B$29+AD24*'"Вес" ПИР'!$B$30+AF24*'"Вес" ПИР'!$B$31)/100 -> 0 | AJ24: на стадии подготовки | AP24: на стадии подготовки | AR24: на стадии подготовки | AT24: на стадии подготовки | BB24: =(AI24*'"Вес" ПИР'!$B$36+AK24*'"Вес" ПИР'!$B$37+AM24*'"Вес" ПИР'!$B$38+AO24*'"Вес" ПИР'!$B$39+AQ24*'"Вес" ПИР'!$B$40+AS24*'"Вес" ПИР'!$B$41+AU24*'"Вес" ПИР'!$B$42+AW24*'"Вес" ПИР'!$B$43+AY24*'"Вес" ПИР'!$B$44+BA24*'"Вес" ПИР'!$B$45)/100 -> 0 | BC24: на стадии подготовки | BE24: на стадии подготовки | BG24: =(BD24*'"Вес" ПИР'!$B$50+BF24*'"Вес" ПИР'!$B$51)/100 -> 0 | BI24: 0 | BK24: 46266 | BL24: =(S24*'"Вес" ПИР'!$B$3+X24*'"Вес" ПИР'!$B$4+AG24*'"Вес" ПИР'!$B$5+BB24*'"Вес" ПИР'!$B$6+BG24*'"Вес" ПИР'!$B$7+BI24*'"Вес" ПИР'!$B$8)/100 -> 0.00375
B25: 2026 | C25: ТОО "5А Engineering" | D25: 115663100 | E25: Акмолинская область | F25: Зерендинский район | G25: Исаковский с.о. | H25: с.Исаковка | I25: Имеется | J25: 1 | K25: на стадии подготовки | M25: на стадии подготовки | O25: на стадии подготовки | Q25: на стадии подготовки | S25: =(J25*'"Вес" ПИР'!$B$13+L25*'"Вес" ПИР'!$B$14+N25*'"Вес" ПИР'!$B$15+P25*'"Вес" ПИР'!$B$16+R25*'"Вес" ПИР'!$B$17)/100 -> 0.05 | T25: 01.12.2025-30.03.2026 | V25: 01.12.2025-30.03.2026 | X25: =(U25*'"Вес" ПИР'!$B$22+W25*'"Вес" ПИР'!$B$23)/100 -> 0 | AG25: =(Z25*'"Вес" ПИР'!$B$28+AB25*'"Вес" ПИР'!$B$29+AD25*'"Вес" ПИР'!$B$30+AF25*'"Вес" ПИР'!$B$31)/100 -> 0 | AJ25: на стадии подготовки | AP25: на стадии подготовки | AR25: на стадии подготовки | AT25: на стадии подготовки | BB25: =(AI25*'"Вес" ПИР'!$B$36+AK25*'"Вес" ПИР'!$B$37+AM25*'"Вес" ПИР'!$B$38+AO25*'"Вес" ПИР'!$B$39+AQ25*'"Вес" ПИР'!$B$40+AS25*'"Вес" ПИР'!$B$41+AU25*'"Вес" ПИР'!$B$42+AW25*'"Вес" ПИР'!$B$43+AY25*'"Вес" ПИР'!$B$44+BA25*'"Вес" ПИР'!$B$45)/100 -> 0 | BC25: на стадии подготовки | BE25: на стадии подготовки | BG25: =(BD25*'"Вес" ПИР'!$B$50+BF25*'"Вес" ПИР'!$B$51)/100 -> 0 | BI25: 0 | BK25: 46266 | BL25: =(S25*'"Вес" ПИР'!$B$3+X25*'"Вес" ПИР'!$B$4+AG25*'"Вес" ПИР'!$B$5+BB25*'"Вес" ПИР'!$B$6+BG25*'"Вес" ПИР'!$B$7+BI25*'"Вес" ПИР'!$B$8)/100 -> 0.00375
B26: 2026 | C26: ТОО "5А Engineering" | D26: 115663400 | E26: Акмолинская область | F26: Зерендинский район | G26: Исаковский с.о. | H26: с.Костомаровка | I26: Имеется | J26: 1 | K26: на стадии подготовки | M26: на стадии подготовки | O26: на стадии подготовки | Q26: на стадии подготовки | S26: =(J26*'"Вес" ПИР'!$B$13+L26*'"Вес" ПИР'!$B$14+N26*'"Вес" ПИР'!$B$15+P26*'"Вес" ПИР'!$B$16+R26*'"Вес" ПИР'!$B$17)/100 -> 0.05 | T26: 01.12.2025-30.03.2026 | V26: 01.12.2025-30.03.2026 | X26: =(U26*'"Вес" ПИР'!$B$22+W26*'"Вес" ПИР'!$B$23)/100 -> 0 | AG26: =(Z26*'"Вес" ПИР'!$B$28+AB26*'"Вес" ПИР'!$B$29+AD26*'"Вес" ПИР'!$B$30+AF26*'"Вес" ПИР'!$B$31)/100 -> 0 | AJ26: на стадии подготовки | AP26: на стадии подготовки | AR26: на стадии подготовки | AT26: на стадии подготовки | BB26: =(AI26*'"Вес" ПИР'!$B$36+AK26*'"Вес" ПИР'!$B$37+AM26*'"Вес" ПИР'!$B$38+AO26*'"Вес" ПИР'!$B$39+AQ26*'"Вес" ПИР'!$B$40+AS26*'"Вес" ПИР'!$B$41+AU26*'"Вес" ПИР'!$B$42+AW26*'"Вес" ПИР'!$B$43+AY26*'"Вес" ПИР'!$B$44+BA26*'"Вес" ПИР'!$B$45)/100 -> 0 | BC26: на стадии подготовки | BE26: на стадии подготовки | BG26: =(BD26*'"Вес" ПИР'!$B$50+BF26*'"Вес" ПИР'!$B$51)/100 -> 0 | BI26: 0 | BK26: 46266 | BL26: =(S26*'"Вес" ПИР'!$B$3+X26*'"Вес" ПИР'!$B$4+AG26*'"Вес" ПИР'!$B$5+BB26*'"Вес" ПИР'!$B$6+BG26*'"Вес" ПИР'!$B$7+BI26*'"Вес" ПИР'!$B$8)/100 -> 0.00375
B27: 2026 | C27: ТОО "5А Engineering" | D27: 115649200 | E27: Акмолинская область | F27: Зерендинский район | G27: Конысбайский с.о. | H27: с.Васильковка | I27: Имеется | J27: 1 | K27: на стадии подготовки | M27: на стадии подготовки | O27: на стадии подготовки | Q27: на стадии подготовки | S27: =(J27*'"Вес" ПИР'!$B$13+L27*'"Вес" ПИР'!$B$14+N27*'"Вес" ПИР'!$B$15+P27*'"Вес" ПИР'!$B$16+R27*'"Вес" ПИР'!$B$17)/100 -> 0.05 | T27: 01.12.2025-30.03.2026 | V27: 01.12.2025-30.03.2026 | X27: =(U27*'"Вес" ПИР'!$B$22+W27*'"Вес" ПИР'!$B$23)/100 -> 0 | AG27: =(Z27*'"Вес" ПИР'!$B$28+AB27*'"Вес" ПИР'!$B$29+AD27*'"Вес" ПИР'!$B$30+AF27*'"Вес" ПИР'!$B$31)/100 -> 0 | AJ27: на стадии подготовки | AP27: на стадии подготовки | AR27: на стадии подготовки | AT27: на стадии подготовки | BB27: =(AI27*'"Вес" ПИР'!$B$36+AK27*'"Вес" ПИР'!$B$37+AM27*'"Вес" ПИР'!$B$38+AO27*'"Вес" ПИР'!$B$39+AQ27*'"Вес" ПИР'!$B$40+AS27*'"Вес" ПИР'!$B$41+AU27*'"Вес" ПИР'!$B$42+AW27*'"Вес" ПИР'!$B$43+AY27*'"Вес" ПИР'!$B$44+BA27*'"Вес" ПИР'!$B$45)/100 -> 0 | BC27: на стадии подготовки | BE27: на стадии подготовки | BG27: =(BD27*'"Вес" ПИР'!$B$50+BF27*'"Вес" ПИР'!$B$51)/100 -> 0 | BI27: 0 | BK27: 46266 | BL27: =(S27*'"Вес" ПИР'!$B$3+X27*'"Вес" ПИР'!$B$4+AG27*'"Вес" ПИР'!$B$5+BB27*'"Вес" ПИР'!$B$6+BG27*'"Вес" ПИР'!$B$7+BI27*'"Вес" ПИР'!$B$8)/100 -> 0.00375
B28: 2026 | C28: ТОО "5А Engineering" | D28: 115649400 | E28: Акмолинская область | F28: Зерендинский район | G28: Конысбайский с.о. | H28: с.Донгулагаш | I28: Имеется | J28: 1 | K28: на стадии подготовки | M28: на стадии подготовки | O28: на стадии подготовки | Q28: на стадии подготовки | S28: =(J28*'"Вес" ПИР'!$B$13+L28*'"Вес" ПИР'!$B$14+N28*'"Вес" ПИР'!$B$15+P28*'"Вес" ПИР'!$B$16+R28*'"Вес" ПИР'!$B$17)/100 -> 0.05 | T28: 01.12.2025-30.03.2026 | V28: 01.12.2025-30.03.2026 | X28: =(U28*'"Вес" ПИР'!$B$22+W28*'"Вес" ПИР'!$B$23)/100 -> 0 | AG28: =(Z28*'"Вес" ПИР'!$B$28+AB28*'"Вес" ПИР'!$B$29+AD28*'"Вес" ПИР'!$B$30+AF28*'"Вес" ПИР'!$B$31)/100 -> 0 | AJ28: на стадии подготовки | AP28: на стадии подготовки | AR28: на стадии подготовки | AT28: на стадии подготовки | BB28: =(AI28*'"Вес" ПИР'!$B$36+AK28*'"Вес" ПИР'!$B$37+AM28*'"Вес" ПИР'!$B$38+AO28*'"Вес" ПИР'!$B$39+AQ28*'"Вес" ПИР'!$B$40+AS28*'"Вес" ПИР'!$B$41+AU28*'"Вес" ПИР'!$B$42+AW28*'"Вес" ПИР'!$B$43+AY28*'"Вес" ПИР'!$B$44+BA28*'"Вес" ПИР'!$B$45)/100 -> 0 | BC28: на стадии подготовки | BE28: на стадии подготовки | BG28: =(BD28*'"Вес" ПИР'!$B$50+BF28*'"Вес" ПИР'!$B$51)/100 -> 0 | BI28: 0 | BK28: 46266 | BL28: =(S28*'"Вес" ПИР'!$B$3+X28*'"Вес" ПИР'!$B$4+AG28*'"Вес" ПИР'!$B$5+BB28*'"Вес" ПИР'!$B$6+BG28*'"Вес" ПИР'!$B$7+BI28*'"Вес" ПИР'!$B$8)/100 -> 0.00375
B29: 2026 | C29: ТОО "5А Engineering" | D29: 115667100 | E29: Акмолинская область | F29: Зерендинский район | G29: Кызылегисский с.о. | H29: с.Кызылегис | I29: Имеется | J29: 1 | K29: на стадии подготовки | M29: на стадии подготовки | O29: на стадии подготовки | Q29: на стадии подготовки | S29: =(J29*'"Вес" ПИР'!$B$13+L29*'"Вес" ПИР'!$B$14+N29*'"Вес" ПИР'!$B$15+P29*'"Вес" ПИР'!$B$16+R29*'"Вес" ПИР'!$B$17)/100 -> 0.05 | T29: 01.12.2025-30.03.2026 | V29: 01.12.2025-30.03.2026 | X29: =(U29*'"Вес" ПИР'!$B$22+W29*'"Вес" ПИР'!$B$23)/100 -> 0 | AG29: =(Z29*'"Вес" ПИР'!$B$28+AB29*'"Вес" ПИР'!$B$29+AD29*'"Вес" ПИР'!$B$30+AF29*'"Вес" ПИР'!$B$31)/100 -> 0 | AJ29: на стадии подготовки | AP29: на стадии подготовки | AR29: на стадии подготовки | AT29: на стадии подготовки | BB29: =(AI29*'"Вес" ПИР'!$B$36+AK29*'"Вес" ПИР'!$B$37+AM29*'"Вес" ПИР'!$B$38+AO29*'"Вес" ПИР'!$B$39+AQ29*'"Вес" ПИР'!$B$40+AS29*'"Вес" ПИР'!$B$41+AU29*'"Вес" ПИР'!$B$42+AW29*'"Вес" ПИР'!$B$43+AY29*'"Вес" ПИР'!$B$44+BA29*'"Вес" ПИР'!$B$45)/100 -> 0 | BC29: на стадии подготовки | BE29: на стадии подготовки | BG29: =(BD29*'"Вес" ПИР'!$B$50+BF29*'"Вес" ПИР'!$B$51)/100 -> 0 | BI29: 0 | BK29: 46266 | BL29: =(S29*'"Вес" ПИР'!$B$3+X29*'"Вес" ПИР'!$B$4+AG29*'"Вес" ПИР'!$B$5+BB29*'"Вес" ПИР'!$B$6+BG29*'"Вес" ПИР'!$B$7+BI29*'"Вес" ПИР'!$B$8)/100 -> 0.00375
B30: 2026 | C30: ТОО "5А Engineering" | D30: 115667700 | E30: Акмолинская область | F30: Зерендинский район | G30: Кызылегисский с.о. | H30: с.Ортаагаш | I30: Имеется | J30: 1 | K30: на стадии подготовки | M30: на стадии подготовки | O30: на стадии подготовки | Q30: на стадии подготовки | S30: =(J30*'"Вес" ПИР'!$B$13+L30*'"Вес" ПИР'!$B$14+N30*'"Вес" ПИР'!$B$15+P30*'"Вес" ПИР'!$B$16+R30*'"Вес" ПИР'!$B$17)/100 -> 0.05 | T30: 01.12.2025-30.03.2026 | V30: 01.12.2025-30.03.2026 | X30: =(U30*'"Вес" ПИР'!$B$22+W30*'"Вес" ПИР'!$B$23)/100 -> 0 | AG30: =(Z30*'"Вес" ПИР'!$B$28+AB30*'"Вес" ПИР'!$B$29+AD30*'"Вес" ПИР'!$B$30+AF30*'"Вес" ПИР'!$B$31)/100 -> 0 | AJ30: на стадии подготовки | AP30: на стадии подготовки | AR30: на стадии подготовки | AT30: на стадии подготовки | BB30: =(AI30*'"Вес" ПИР'!$B$36+AK30*'"Вес" ПИР'!$B$37+AM30*'"Вес" ПИР'!$B$38+AO30*'"Вес" ПИР'!$B$39+AQ30*'"Вес" ПИР'!$B$40+AS30*'"Вес" ПИР'!$B$41+AU30*'"Вес" ПИР'!$B$42+AW30*'"Вес" ПИР'!$B$43+AY30*'"Вес" ПИР'!$B$44+BA30*'"Вес" ПИР'!$B$45)/100 -> 0 | BC30: на стадии подготовки | BE30: на стадии подготовки | BG30: =(BD30*'"Вес" ПИР'!$B$50+BF30*'"Вес" ПИР'!$B$51)/100 -> 0 | BI30: 0 | BK30: 46266 | BL30: =(S30*'"Вес" ПИР'!$B$3+X30*'"Вес" ПИР'!$B$4+AG30*'"Вес" ПИР'!$B$5+BB30*'"Вес" ПИР'!$B$6+BG30*'"Вес" ПИР'!$B$7+BI30*'"Вес" ПИР'!$B$8)/100 -> 0.00375
B31: 2026 | C31: ТОО "5А Engineering" | D31: 115651100 | E31: Акмолинская область | F31: Зерендинский район | G31: Кызылсаянский с.о. | H31: с.Кызылсая | I31: Имеется | K31: на стадии подготовки | M31: на стадии подготовки | O31: на стадии подготовки | Q31: на стадии подготовки | S31: =(J31*'"Вес" ПИР'!$B$13+L31*'"Вес" ПИР'!$B$14+N31*'"Вес" ПИР'!$B$15+P31*'"Вес" ПИР'!$B$16+R31*'"Вес" ПИР'!$B$17)/100 -> 0 | T31: 01.12.2025-30.03.2026 | V31: 01.12.2025-30.03.2026 | X31: =(U31*'"Вес" ПИР'!$B$22+W31*'"Вес" ПИР'!$B$23)/100 -> 0 | AG31: =(Z31*'"Вес" ПИР'!$B$28+AB31*'"Вес" ПИР'!$B$29+AD31*'"Вес" ПИР'!$B$30+AF31*'"Вес" ПИР'!$B$31)/100 -> 0 | AJ31: на стадии подготовки | AP31: на стадии подготовки | AR31: на стадии подготовки | AT31: на стадии подготовки | BB31: =(AI31*'"Вес" ПИР'!$B$36+AK31*'"Вес" ПИР'!$B$37+AM31*'"Вес" ПИР'!$B$38+AO31*'"Вес" ПИР'!$B$39+AQ31*'"Вес" ПИР'!$B$40+AS31*'"Вес" ПИР'!$B$41+AU31*'"Вес" ПИР'!$B$42+AW31*'"Вес" ПИР'!$B$43+AY31*'"Вес" ПИР'!$B$44+BA31*'"Вес" ПИР'!$B$45)/100 -> 0 | BC31: на стадии подготовки | BE31: на стадии подготовки | BG31: =(BD31*'"Вес" ПИР'!$B$50+BF31*'"Вес" ПИР'!$B$51)/100 -> 0 | BI31: 0 | BK31: 46266 | BL31: =(S31*'"Вес" ПИР'!$B$3+X31*'"Вес" ПИР'!$B$4+AG31*'"Вес" ПИР'!$B$5+BB31*'"Вес" ПИР'!$B$6+BG31*'"Вес" ПИР'!$B$7+BI31*'"Вес" ПИР'!$B$8)/100 -> 0
B32: 2026 | C32: ТОО "5А Engineering" | D32: 115652400 | E32: Акмолинская область | F32: Зерендинский район | G32: Ортакский с.о. | H32: с.Кызылтан | I32: Имеется | K32: на стадии подготовки | M32: на стадии подготовки | O32: на стадии подготовки | Q32: на стадии подготовки | S32: =(J32*'"Вес" ПИР'!$B$13+L32*'"Вес" ПИР'!$B$14+N32*'"Вес" ПИР'!$B$15+P32*'"Вес" ПИР'!$B$16+R32*'"Вес" ПИР'!$B$17)/100 -> 0 | T32: 01.12.2025-30.03.2026 | V32: 01.12.2025-30.03.2026 | X32: =(U32*'"Вес" ПИР'!$B$22+W32*'"Вес" ПИР'!$B$23)/100 -> 0 | AG32: =(Z32*'"Вес" ПИР'!$B$28+AB32*'"Вес" ПИР'!$B$29+AD32*'"Вес" ПИР'!$B$30+AF32*'"Вес" ПИР'!$B$31)/100 -> 0 | AJ32: на стадии подготовки | AP32: на стадии подготовки | AR32: на стадии подготовки | AT32: на стадии подготовки | BB32: =(AI32*'"Вес" ПИР'!$B$36+AK32*'"Вес" ПИР'!$B$37+AM32*'"Вес" ПИР'!$B$38+AO32*'"Вес" ПИР'!$B$39+AQ32*'"Вес" ПИР'!$B$40+AS32*'"Вес" ПИР'!$B$41+AU32*'"Вес" ПИР'!$B$42+AW32*'"Вес" ПИР'!$B$43+AY32*'"Вес" ПИР'!$B$44+BA32*'"Вес" ПИР'!$B$45)/100 -> 0 | BC32: на стадии подготовки | BE32: на стадии подготовки | BG32: =(BD32*'"Вес" ПИР'!$B$50+BF32*'"Вес" ПИР'!$B$51)/100 -> 0 | BI32: 0 | BK32: 46266 | BL32: =(S32*'"Вес" ПИР'!$B$3+X32*'"Вес" ПИР'!$B$4+AG32*'"Вес" ПИР'!$B$5+BB32*'"Вес" ПИР'!$B$6+BG32*'"Вес" ПИР'!$B$7+BI32*'"Вес" ПИР'!$B$8)/100 -> 0
B33: 2026 | C33: ТОО "5А Engineering" | D33: 115653400 | E33: Акмолинская область | F33: Зерендинский район | G33: Приреченский с.о. | H33: с.Павловка | I33: Имеется | K33: на стадии подготовки | M33: на стадии подготовки | O33: на стадии подготовки | Q33: на стадии подготовки | S33: =(J33*'"Вес" ПИР'!$B$13+L33*'"Вес" ПИР'!$B$14+N33*'"Вес" ПИР'!$B$15+P33*'"Вес" ПИР'!$B$16+R33*'"Вес" ПИР'!$B$17)/100 -> 0 | T33: 01.12.2025-30.03.2026 | V33: 01.12.2025-30.03.2026 | X33: =(U33*'"Вес" ПИР'!$B$22+W33*'"Вес" ПИР'!$B$23)/100 -> 0 | AG33: =(Z33*'"Вес" ПИР'!$B$28+AB33*'"Вес" ПИР'!$B$29+AD33*'"Вес" ПИР'!$B$30+AF33*'"Вес" ПИР'!$B$31)/100 -> 0 | AJ33: на стадии подготовки | AP33: на стадии подготовки | AR33: на стадии подготовки | AT33: на стадии подготовки | BB33: =(AI33*'"Вес" ПИР'!$B$36+AK33*'"Вес" ПИР'!$B$37+AM33*'"Вес" ПИР'!$B$38+AO33*'"Вес" ПИР'!$B$39+AQ33*'"Вес" ПИР'!$B$40+AS33*'"Вес" ПИР'!$B$41+AU33*'"Вес" ПИР'!$B$42+AW33*'"Вес" ПИР'!$B$43+AY33*'"Вес" ПИР'!$B$44+BA33*'"Вес" ПИР'!$B$45)/100 -> 0 | BC33: на стадии подготовки | BE33: на стадии подготовки | BG33: =(BD33*'"Вес" ПИР'!$B$50+BF33*'"Вес" ПИР'!$B$51)/100 -> 0 | BI33: 0 | BK33: 46266 | BL33: =(S33*'"Вес" ПИР'!$B$3+X33*'"Вес" ПИР'!$B$4+AG33*'"Вес" ПИР'!$B$5+BB33*'"Вес" ПИР'!$B$6+BG33*'"Вес" ПИР'!$B$7+BI33*'"Вес" ПИР'!$B$8)/100 -> 0
B34: 2026 | C34: ТОО "5А Engineering" | D34: 115665400 | E34: Акмолинская область | F34: Зерендинский район | G34: с.о.им.Канай би | H34: с.Игилик | I34: Имеется | K34: на стадии подготовки | M34: на стадии подготовки | O34: на стадии подготовки | Q34: на стадии подготовки | S34: =(J34*'"Вес" ПИР'!$B$13+L34*'"Вес" ПИР'!$B$14+N34*'"Вес" ПИР'!$B$15+P34*'"Вес" ПИР'!$B$16+R34*'"Вес" ПИР'!$B$17)/100 -> 0 | T34: 01.12.2025-30.03.2026 | V34: 01.12.2025-30.03.2026 | X34: =(U34*'"Вес" ПИР'!$B$22+W34*'"Вес" ПИР'!$B$23)/100 -> 0 | AG34: =(Z34*'"Вес" ПИР'!$B$28+AB34*'"Вес" ПИР'!$B$29+AD34*'"Вес" ПИР'!$B$30+AF34*'"Вес" ПИР'!$B$31)/100 -> 0 | AJ34: на стадии подготовки | AP34: на стадии подготовки | AR34: на стадии подготовки | AT34: на стадии подготовки | BB34: =(AI34*'"Вес" ПИР'!$B$36+AK34*'"Вес" ПИР'!$B$37+AM34*'"Вес" ПИР'!$B$38+AO34*'"Вес" ПИР'!$B$39+AQ34*'"Вес" ПИР'!$B$40+AS34*'"Вес" ПИР'!$B$41+AU34*'"Вес" ПИР'!$B$42+AW34*'"Вес" ПИР'!$B$43+AY34*'"Вес" ПИР'!$B$44+BA34*'"Вес" ПИР'!$B$45)/100 -> 0 | BC34: на стадии подготовки | BE34: на стадии подготовки | BG34: =(BD34*'"Вес" ПИР'!$B$50+BF34*'"Вес" ПИР'!$B$51)/100 -> 0 | BI34: 0 | BK34: 46266 | BL34: =(S34*'"Вес" ПИР'!$B$3+X34*'"Вес" ПИР'!$B$4+AG34*'"Вес" ПИР'!$B$5+BB34*'"Вес" ПИР'!$B$6+BG34*'"Вес" ПИР'!$B$7+BI34*'"Вес" ПИР'!$B$8)/100 -> 0
B35: 2026 | C35: ТОО "5А Engineering" | D35: 115665100 | E35: Акмолинская область | F35: Зерендинский район | G35: с.о.им.Канай би | H35: с.Карауыл Канай-бия | I35: Имеется | K35: на стадии подготовки | M35: на стадии подготовки | O35: на стадии подготовки | Q35: на стадии подготовки | S35: =(J35*'"Вес" ПИР'!$B$13+L35*'"Вес" ПИР'!$B$14+N35*'"Вес" ПИР'!$B$15+P35*'"Вес" ПИР'!$B$16+R35*'"Вес" ПИР'!$B$17)/100 -> 0 | T35: 01.12.2025-30.03.2026 | V35: 01.12.2025-30.03.2026 | X35: =(U35*'"Вес" ПИР'!$B$22+W35*'"Вес" ПИР'!$B$23)/100 -> 0 | AG35: =(Z35*'"Вес" ПИР'!$B$28+AB35*'"Вес" ПИР'!$B$29+AD35*'"Вес" ПИР'!$B$30+AF35*'"Вес" ПИР'!$B$31)/100 -> 0 | AJ35: на стадии подготовки | AP35: на стадии подготовки | AR35: на стадии подготовки | AT35: на стадии подготовки | BB35: =(AI35*'"Вес" ПИР'!$B$36+AK35*'"Вес" ПИР'!$B$37+AM35*'"Вес" ПИР'!$B$38+AO35*'"Вес" ПИР'!$B$39+AQ35*'"Вес" ПИР'!$B$40+AS35*'"Вес" ПИР'!$B$41+AU35*'"Вес" ПИР'!$B$42+AW35*'"Вес" ПИР'!$B$43+AY35*'"Вес" ПИР'!$B$44+BA35*'"Вес" ПИР'!$B$45)/100 -> 0 | BC35: на стадии подготовки | BE35: на стадии подготовки | BG35: =(BD35*'"Вес" ПИР'!$B$50+BF35*'"Вес" ПИР'!$B$51)/100 -> 0 | BI35: 0 | BK35: 46266 | BL35: =(S35*'"Вес" ПИР'!$B$3+X35*'"Вес" ПИР'!$B$4+AG35*'"Вес" ПИР'!$B$5+BB35*'"Вес" ПИР'!$B$6+BG35*'"Вес" ПИР'!$B$7+BI35*'"Вес" ПИР'!$B$8)/100 -> 0
B36: 2026 | C36: ТОО "5А Engineering" | D36: 115673100 | E36: Акмолинская область | F36: Зерендинский район | G36: с.о.им.Сакена Сейфуллина | H36: с.Бирлестик | I36: Имеется | K36: на стадии подготовки | M36: на стадии подготовки | O36: на стадии подготовки | Q36: на стадии подготовки | S36: =(J36*'"Вес" ПИР'!$B$13+L36*'"Вес" ПИР'!$B$14+N36*'"Вес" ПИР'!$B$15+P36*'"Вес" ПИР'!$B$16+R36*'"Вес" ПИР'!$B$17)/100 -> 0 | T36: 01.12.2025-30.03.2026 | V36: 01.12.2025-30.03.2026 | X36: =(U36*'"Вес" ПИР'!$B$22+W36*'"Вес" ПИР'!$B$23)/100 -> 0 | AG36: =(Z36*'"Вес" ПИР'!$B$28+AB36*'"Вес" ПИР'!$B$29+AD36*'"Вес" ПИР'!$B$30+AF36*'"Вес" ПИР'!$B$31)/100 -> 0 | AJ36: на стадии подготовки | AP36: на стадии подготовки | AR36: на стадии подготовки | AT36: на стадии подготовки | BB36: =(AI36*'"Вес" ПИР'!$B$36+AK36*'"Вес" ПИР'!$B$37+AM36*'"Вес" ПИР'!$B$38+AO36*'"Вес" ПИР'!$B$39+AQ36*'"Вес" ПИР'!$B$40+AS36*'"Вес" ПИР'!$B$41+AU36*'"Вес" ПИР'!$B$42+AW36*'"Вес" ПИР'!$B$43+AY36*'"Вес" ПИР'!$B$44+BA36*'"Вес" ПИР'!$B$45)/100 -> 0 | BC36: на стадии подготовки | BE36: на стадии подготовки | BG36: =(BD36*'"Вес" ПИР'!$B$50+BF36*'"Вес" ПИР'!$B$51)/100 -> 0 | BI36: 0 | BK36: 46266 | BL36: =(S36*'"Вес" ПИР'!$B$3+X36*'"Вес" ПИР'!$B$4+AG36*'"Вес" ПИР'!$B$5+BB36*'"Вес" ПИР'!$B$6+BG36*'"Вес" ПИР'!$B$7+BI36*'"Вес" ПИР'!$B$8)/100 -> 0
B37: 2026 | C37: ТОО "5А Engineering" | D37: 115673500 | E37: Акмолинская область | F37: Зерендинский район | G37: с.о.им.Сакена Сейфуллина | H37: с.Сейфуллино | I37: Имеется | K37: на стадии подготовки | M37: на стадии подготовки | O37: на стадии подготовки | Q37: на стадии подготовки | S37: =(J37*'"Вес" ПИР'!$B$13+L37*'"Вес" ПИР'!$B$14+N37*'"Вес" ПИР'!$B$15+P37*'"Вес" ПИР'!$B$16+R37*'"Вес" ПИР'!$B$17)/100 -> 0 | T37: 01.12.2025-30.03.2026 | V37: 01.12.2025-30.03.2026 | X37: =(U37*'"Вес" ПИР'!$B$22+W37*'"Вес" ПИР'!$B$23)/100 -> 0 | AG37: =(Z37*'"Вес" ПИР'!$B$28+AB37*'"Вес" ПИР'!$B$29+AD37*'"Вес" ПИР'!$B$30+AF37*'"Вес" ПИР'!$B$31)/100 -> 0 | AJ37: на стадии подготовки | AP37: на стадии подготовки | AR37: на стадии подготовки | AT37: на стадии подготовки | BB37: =(AI37*'"Вес" ПИР'!$B$36+AK37*'"Вес" ПИР'!$B$37+AM37*'"Вес" ПИР'!$B$38+AO37*'"Вес" ПИР'!$B$39+AQ37*'"Вес" ПИР'!$B$40+AS37*'"Вес" ПИР'!$B$41+AU37*'"Вес" ПИР'!$B$42+AW37*'"Вес" ПИР'!$B$43+AY37*'"Вес" ПИР'!$B$44+BA37*'"Вес" ПИР'!$B$45)/100 -> 0 | BC37: на стадии подготовки | BE37: на стадии подготовки | BG37: =(BD37*'"Вес" ПИР'!$B$50+BF37*'"Вес" ПИР'!$B$51)/100 -> 0 | BI37: 0 | BK37: 46266 | BL37: =(S37*'"Вес" ПИР'!$B$3+X37*'"Вес" ПИР'!$B$4+AG37*'"Вес" ПИР'!$B$5+BB37*'"Вес" ПИР'!$B$6+BG37*'"Вес" ПИР'!$B$7+BI37*'"Вес" ПИР'!$B$8)/100 -> 0
B38: 2026 | C38: ТОО "5А Engineering" | D38: 115655100 | E38: Акмолинская область | F38: Зерендинский район | G38: с.о.Малика Габдуллина | H38: с.Малика Габдуллина | I38: Имеется | K38: на стадии подготовки | M38: на стадии подготовки | O38: на стадии подготовки | Q38: на стадии подготовки | S38: =(J38*'"Вес" ПИР'!$B$13+L38*'"Вес" ПИР'!$B$14+N38*'"Вес" ПИР'!$B$15+P38*'"Вес" ПИР'!$B$16+R38*'"Вес" ПИР'!$B$17)/100 -> 0 | T38: 01.12.2025-30.03.2026 | V38: 01.12.2025-30.03.2026 | X38: =(U38*'"Вес" ПИР'!$B$22+W38*'"Вес" ПИР'!$B$23)/100 -> 0 | AG38: =(Z38*'"Вес" ПИР'!$B$28+AB38*'"Вес" ПИР'!$B$29+AD38*'"Вес" ПИР'!$B$30+AF38*'"Вес" ПИР'!$B$31)/100 -> 0 | AJ38: на стадии подготовки | AP38: на стадии подготовки | AR38: на стадии подготовки | AT38: на стадии подготовки | BB38: =(AI38*'"Вес" ПИР'!$B$36+AK38*'"Вес" ПИР'!$B$37+AM38*'"Вес" ПИР'!$B$38+AO38*'"Вес" ПИР'!$B$39+AQ38*'"Вес" ПИР'!$B$40+AS38*'"Вес" ПИР'!$B$41+AU38*'"Вес" ПИР'!$B$42+AW38*'"Вес" ПИР'!$B$43+AY38*'"Вес" ПИР'!$B$44+BA38*'"Вес" ПИР'!$B$45)/100 -> 0 | BC38: на стадии подготовки | BE38: на стадии подготовки | BG38: =(BD38*'"Вес" ПИР'!$B$50+BF38*'"Вес" ПИР'!$B$51)/100 -> 0 | BI38: 0 | BK38: 46266 | BL38: =(S38*'"Вес" ПИР'!$B$3+X38*'"Вес" ПИР'!$B$4+AG38*'"Вес" ПИР'!$B$5+BB38*'"Вес" ПИР'!$B$6+BG38*'"Вес" ПИР'!$B$7+BI38*'"Вес" ПИР'!$B$8)/100 -> 0
B39: 2026 | C39: ТОО "5А Engineering" | D39: 115671200 | E39: Акмолинская область | F39: Зерендинский район | G39: Садовый с.о. | H39: с.Еликти | I39: Имеется | K39: на стадии подготовки | M39: на стадии подготовки | O39: на стадии подготовки | Q39: на стадии подготовки | S39: =(J39*'"Вес" ПИР'!$B$13+L39*'"Вес" ПИР'!$B$14+N39*'"Вес" ПИР'!$B$15+P39*'"Вес" ПИР'!$B$16+R39*'"Вес" ПИР'!$B$17)/100 -> 0 | T39: 01.12.2025-30.03.2026 | V39: 01.12.2025-30.03.2026 | X39: =(U39*'"Вес" ПИР'!$B$22+W39*'"Вес" ПИР'!$B$23)/100 -> 0 | AG39: =(Z39*'"Вес" ПИР'!$B$28+AB39*'"Вес" ПИР'!$B$29+AD39*'"Вес" ПИР'!$B$30+AF39*'"Вес" ПИР'!$B$31)/100 -> 0 | AJ39: на стадии подготовки | AP39: на стадии подготовки | AR39: на стадии подготовки | AT39: на стадии подготовки | BB39: =(AI39*'"Вес" ПИР'!$B$36+AK39*'"Вес" ПИР'!$B$37+AM39*'"Вес" ПИР'!$B$38+AO39*'"Вес" ПИР'!$B$39+AQ39*'"Вес" ПИР'!$B$40+AS39*'"Вес" ПИР'!$B$41+AU39*'"Вес" ПИР'!$B$42+AW39*'"Вес" ПИР'!$B$43+AY39*'"Вес" ПИР'!$B$44+BA39*'"Вес" ПИР'!$B$45)/100 -> 0 | BC39: на стадии подготовки | BE39: на стадии подготовки | BG39: =(BD39*'"Вес" ПИР'!$B$50+BF39*'"Вес" ПИР'!$B$51)/100 -> 0 | BI39: 0 | BK39: 46266 | BL39: =(S39*'"Вес" ПИР'!$B$3+X39*'"Вес" ПИР'!$B$4+AG39*'"Вес" ПИР'!$B$5+BB39*'"Вес" ПИР'!$B$6+BG39*'"Вес" ПИР'!$B$7+BI39*'"Вес" ПИР'!$B$8)/100 -> 0
